Workbook

Sheet GDP data
A1: country | B1: 44927 | C1: 44958 | D1: 44986 | E1: 45017 | F1: 45047 | G1: 45078 | H1: 45108 | I1: 45139 | J1: 45170 | K1: 45200 | L1: 45231 | M1: 45261 | N1: 45292 | O1: 45323 | P1: 45352 | Q1: 45383 | R1: 45413 | S1: 45444 | T1: 45474 | U1: 45505 | V1: 45536 | W1: 45566 | X1: 45597 | Y1: 45627 | Z1: 45658 | AA1: 45689 | AB1: 45717 | AC1: 45748 | AD1: 45778 | AE1: 45809 | AF1: 45839 | AG1: 45870 | AH1: 45901 | AI1: 45931 | AJ1: 45962 | AK1: 45992 | AL1: 46023 | AM1: 46054 | AN1: 46082 | AO1: 46113 | AP1: 46143 | AQ1: 46174 | AR1: 46204 | AS1: 46235 | AT1: 46266 | AU1: 46296 | AV1: 46327 | AW1: 46357
A2: Australia | B2: 2.8 | C2: 2.8 | D2: 2.8 | E2: 2.2 | F2: 2.2 | G2: 2.2 | H2: 2.2 | I2: 2.2 | J2: 2.2 | K2: 1.3 | L2: 1.3 | M2: 1.3 | N2: 1.1 | O2: 1.1 | P2: 1.1 | Q2: 0.9 | R2: 0.9 | S2: 0.9 | T2: 0.8 | U2: 0.8 | V2: 0.8 | W2: 1.2 | X2: 1.2 | Y2: 1.2 | Z2: 1.3 | AA2: 1.3 | AB2: 1.3 | AC2: 1.9 | AD2: 1.9 | AE2: 1.9 | AF2: 2.1 | AG2: 2.1 | AH2: 2.1 | AI2: 2.6 | AJ2: 2.6 | AK2: 2.6 | AL2: 2.5 | AM2: 2.5 | AN2: 2.5 | AO2: 2.1 | AP2: 2.1 | AQ2: 2.1 | AR2: 2.1 | AS2: 2.1 | AT2: 2.1 | AU2: 1.5 | AV2: 1.5 | AW2: 1.5 | AY2: Valeur | AZ2: rating
A3: Canada | B3: 3.1 | C3: 3.1 | D3: 3.1 | E3: 2.1 | F3: 2.1 | G3: 2.1 | H3: 1.3 | I3: 1.3 | J3: 1.3 | K3: 1.3 | L3: 1.3 | M3: 1.3 | N3: 1 | O3: 1 | P3: 1 | Q3: 1.7 | R3: 1.7 | S3: 1.7 | T3: 2.4 | U3: 2.4 | V3: 2.4 | W3: 3.1 | X3: 3.1 | Y3: 3.1 | Z3: 3.1 | AA3: 3.1 | AB3: 3.1 | AC3: 2 | AD3: 2 | AE3: 2 | AF3: 1.7 | AG3: 1.7 | AH3: 1.7 | AI3: 0.7 | AJ3: 0.7 | AK3: 0.7 | AL3: 0.1 | AM3: 0.1 | AN3: 0.1 | AO3: 1.1 | AP3: 1.1 | AQ3: 1.1 | AR3: 0.9 | AS3: 0.9 | AT3: 0.9 | AU3: 1.5 | AV3: 1.5 | AW3: 1.5 | AY3: 5 | AZ3: 10
A4: Japan | B4: 2.1 | C4: 2.1 | D4: 2.1 | E4: 1.2 | F4: 1.2 | G4: 1.2 | H4: 0.2 | I4: 0.2 | J4: 0.2 | K4: 0.1 | L4: 0.1 | M4: 0.1 | N4: -0.9 | O4: -0.9 | P4: -0.9 | Q4: -0.9 | R4: -0.9 | S4: -0.9 | T4: 1.1 | U4: 1.1 | V4: 1.1 | W4: 0.9 | X4: 0.9 | Y4: 0.9 | Z4: 1.6 | AA4: 1.6 | AB4: 1.6 | AC4: 2.1 | AD4: 2.1 | AE4: 2.1 | AF4: 0.6 | AG4: 0.6 | AH4: 0.6 | AI4: 0.4 | AJ4: 0.4 | AK4: 0.4 | AL4: 0.5 | AM4: 0.5 | AN4: 0.5 | AO4: 0.7 | AP4: 0.7 | AQ4: 0.7 | AR4: 0.9 | AS4: 0.9 | AT4: 0.9 | AU4: 1.1 | AV4: 1.1 | AW4: 1.1 | AY4: 4 | AZ4: 8
A5: New Zealand | B5: 3.1 | C5: 3.1 | D5: 3.1 | E5: 3 | F5: 3 | G5: 3 | H5: 1.2 | I5: 1.2 | J5: 1.2 | K5: 1.4 | L5: 1.4 | M5: 1.4 | N5: 1.6 | O5: 1.6 | P5: 1.6 | Q5: 0.1 | R5: 0.1 | S5: 0.1 | T5: -1.2 | U5: -1.2 | V5: -1.2 | W5: -1.6 | X5: -1.6 | Y5: -1.6 | Z5: -0.7 | AA5: -0.7 | AB5: -0.7 | AC5: -0.9 | AD5: -0.9 | AE5: -0.9 | AF5: 1.2 | AG5: 1.2 | AH5: 1.2 | AI5: 1.6 | AJ5: 1.6 | AK5: 1.6 | AL5: 1.7 | AM5: 1.7 | AN5: 1.7 | AO5: 2.6 | AP5: 2.6 | AQ5: 2.6 | AR5: 2 | AS5: 2 | AT5: 2 | AU5: 2.1 | AV5: 2.1 | AW5: 2.1 | AY5: 3 | AZ5: 6
A6: Switzerland | B6: 2 | C6: 2 | D6: 2 | E6: 1 | F6: 1 | G6: 1 | H6: 0.8 | I6: 0.8 | J6: 0.8 | K6: 1.1 | L6: 1.1 | M6: 1.1 | N6: 0.1 | O6: 0.1 | P6: 0.1 | Q6: 1.6 | R6: 1.6 | S6: 1.6 | T6: 1.6 | U6: 1.6 | V6: 1.6 | W6: 1.3 | X6: 1.3 | Y6: 1.3 | Z6: 2.6 | AA6: 2.6 | AB6: 2.6 | AC6: 1.4 | AD6: 1.4 | AE6: 1.4 | AF6: 0.7 | AG6: 0.7 | AH6: 0.7 | AI6: 1.1 | AJ6: 1.1 | AK6: 1.1 | AL6: 0.4 | AM6: 0.4 | AN6: 0.4 | AO6: 2.3 | AP6: 2.3 | AQ6: 2.3 | AR6: 1.8 | AS6: 1.8 | AT6: 1.8 | AU6: 1.7 | AV6: 1.7 | AW6: 1.7 | AY6: 2 | AZ6: 4
A7: United Kingdom | B7: 1 | C7: 1 | D7: 1 | E7: 0.5 | F7: 0.5 | G7: 0.5 | H7: 0.1 | I7: 0.1 | J7: 0.1 | K7: -0.5 | L7: -0.5 | M7: -0.5 | N7: 0.2 | O7: 0.2 | P7: 0.2 | Q7: 0.8 | R7: 0.8 | S7: 0.8 | T7: 1.2 | U7: 1.2 | V7: 1.2 | W7: 2 | X7: 2 | Y7: 2 | Z7: 1.8 | AA7: 1.8 | AB7: 1.8 | AC7: 1.3 | AD7: 1.3 | AE7: 1.3 | AF7: 1.2 | AG7: 1.2 | AH7: 1.2 | AI7: 0.9 | AJ7: 0.9 | AK7: 0.9 | AL7: 0.9 | AM7: 0.9 | AN7: 0.9 | AO7: 1.2 | AP7: 1.2 | AQ7: 1.2 | AR7: 1.7 | AS7: 1.7 | AT7: 1.7 | AU7: 1.4 | AV7: 1.4 | AW7: 1.4 | AY7: 1 | AZ7: 2
A8: United States | B8: 2.3 | C8: 2.3 | D8: 2.3 | E8: 2.8 | F8: 2.8 | G8: 2.8 | H8: 3.2 | I8: 3.2 | J8: 3.2 | K8: 3.4 | L8: 3.4 | M8: 3.4 | N8: 2.9 | O8: 2.9 | P8: 2.9 | Q8: 3.1 | R8: 3.1 | S8: 3.1 | T8: 2.8 | U8: 2.8 | V8: 2.8 | W8: 2.4 | X8: 2.4 | Y8: 2.4 | Z8: 2 | AA8: 2 | AB8: 2 | AC8: 2.1 | AD8: 2.1 | AE8: 2.1 | AF8: 2.3 | AG8: 2.3 | AH8: 2.3 | AI8: 2 | AJ8: 2 | AK8: 2 | AL8: 2.7 | AM8: 2.7 | AN8: 2.7 | AO8: 2.1 | AP8: 2.1 | AQ8: 2.1 | AR8: 1.8 | AS8: 1.8 | AT8: 1.8 | AU8: 1.6 | AV8: 1.6 | AW8: 1.6 | AY8: 0 | AZ8: 0
A9: Euro area (19 countries) | B9: 1.2 | C9: 1.2 | D9: 1.2 | E9: 0.5 | F9: 0.5 | G9: 0.5 | H9: 0.1 | I9: 0.1 | J9: 0.1 | K9: 0.2 | L9: 0.2 | M9: 0.2 | N9: 0.8 | O9: 0.8 | P9: 0.8 | Q9: 0.9 | R9: 0.9 | S9: 0.9 | T9: 1.2 | U9: 1.2 | V9: 1.2 | W9: 1.5 | X9: 1.5 | Y9: 1.5 | Z9: 1.6 | AA9: 1.6 | AB9: 1.6 | AC9: 1.4 | AD9: 1.4 | AE9: 1.4 | AF9: 1.2 | AG9: 1.2 | AH9: 1.2 | AI9: 1.1 | AJ9: 1.1 | AK9: 1.1 | AL9: 0.6 | AM9: 0.6 | AN9: 0.6 | AO9: 1.2 | AP9: 1.2 | AQ9: 1.2 | AR9: 1 | AS9: 1 | AT9: 1 | AU9: 0.7 | AV9: 0.7 | AW9: 0.7 | AY9: -1 | AZ9: -2
AY10: -2 | AZ10: -4
A11: Pair | B11: 44927 | C11: 44958 | D11: 44986 | E11: 45017 | F11: 45047 | G11: 45078 | H11: 45108 | I11: 45139 | J11: 45170 | K11: 45200 | L11: 45231 | M11: 45261 | N11: 45292 | O11: 45323 | P11: 45352 | Q11: 45383 | R11: 45413 | S11: 45444 | T11: 45474 | U11: 45505 | V11: 45536 | W11: 45566 | X11: 45597 | Y11: 45627 | Z11: 45658 | AA11: 45689 | AB11: 45717 | AC11: 45748 | AD11: 45778 | AE11: 45809 | AF11: 45839 | AG11: 45870 | AH11: 45901 | AI11: 45931 | AJ11: 45962 | AK11: 45992 | AL11: 46023 | AM11: 46054 | AN11: 46082 | AO11: 46113 | AP11: 46143 | AQ11: 46174 | AR11: 46204 | AS11: 46235 | AT11: 46266 | AU11: 46296 | AV11: 46327 | AW11: 46357 | AY11: -3 | AZ11: -6
A12: USD JPY | B12: =B8-B3 | C12: =C8-C3 | D12: =D8-D3 | E12: =E8-E3 | F12: =F8-F3 | G12: =G8-G3 | H12: =H8-H3 | I12: =I8-I3 | ... AW12: =AW8-AW3 | AY12: -4 | AZ12: -8
A13: USD CHF | B13: =B8-B6 | C13: =C8-C6 | D13: =D8-D6 | E13: =E8-E6 | F13: =F8-F6 | G13: =G8-G6 | H13: =H8-H6 | I13: =I8-I6 | ... AW13: =AW8-AW6 | AY13: -5 | AZ13: -10
A14: USD CAD | B14: =B8-B3 | C14: =C8-C3 | D14: =D8-D3 | E14: =E8-E3 | F14: =F8-F3 | G14: =G8-G3 | H14: =H8-H3 | I14: =I8-I3 | ... AW14: =AW8-AW3
A15: EUR USD | B15: =B9-B8 | C15: =C9-C8 | D15: =D9-D8 | E15: =E9-E8 | F15: =F9-F8 | G15: =G9-G8 | H15: =H9-H8 | I15: =I9-I8 | ... AW15: =AW9-AW8
A16: EUR JPY | B16: =B9-B4 | C16: =C9-C4 | D16: =D9-D4 | E16: =E9-E4 | F16: =F9-F4 | G16: =G9-G4 | H16: =H9-H4 | I16: =I9-I4 | ... AW16: =AW9-AW4
A17: EUR CHF | B17: =B9-B6 | C17: =C9-C6 | D17: =D9-D6 | E17: =E9-E6 | F17: =F9-F6 | G17: =G9-G6 | H17: =H9-H6 | I17: =I9-I6 | ... AW17: =AW9-AW6
A18: EUR GBP | B18: =B9-B7 | C18: =C9-C7 | D18: =D9-D7 | E18: =E9-E7 | F18: =F9-F7 | G18: =G9-G7 | H18: =H9-H7 | I18: =I9-I7 | ... AW18: =AW9-AW7
A19: EUR CAD | B19: =B9-B3 | C19: =C9-C3 | D19: =D9-D3 | E19: =E9-E3 | F19: =F9-F3 | G19: =G9-G3 | H19: =H9-H3 | I19: =I9-I3 | ... AW19: =AW9-AW3
A20: EUR AUD | B20: =B9-B2 | C20: =C9-C2 | D20: =D9-D2 | E20: =E9-E2 | F20: =F9-F2 | G20: =G9-G2 | H20: =H9-H2 | I20: =I9-I2 | ... AW20: =AW9-AW2
A21: EUR NZD | B21: =B9-B5 | C21: =C9-C5 | D21: =D9-D5 | E21: =E9-E5 | F21: =F9-F5 | G21: =G9-G5 | H21: =H9-H5 | I21: =I9-I5 | ... AW21: =AW9-AW5
A22: GBP USD | B22: =B7-B8 | C22: =C7-C8 | D22: =D7-D8 | E22: =E7-E8 | F22: =F7-F8 | G22: =G7-G8 | H22: =H7-H8 | I22: =I7-I8 | ... AW22: =AW7-AW8
A23: GBP JPY | B23: =B7-B4 | C23: =C7-C4 | D23: =D7-D4 | E23: =E7-E4 | F23: =F7-F4 | G23: =G7-G4 | H23: =H7-H4 | I23: =I7-I4 | ... AW23: =AW7-AW4
A24: GBP CHF | B24: =B7-B6 | C24: =C7-C6 | D24: =D7-D6 | E24: =E7-E6 | F24: =F7-F6 | G24: =G7-G6 | H24: =H7-H6 | I24: =I7-I6 | ... AW24: =AW7-AW6
A25: GBP CAD | B25: =B7-B3 | C25: =C7-C3 | D25: =D7-D3 | E25: =E7-E3 | F25: =F7-F3 | G25: =G7-G3 | H25: =H7-H3 | I25: =I7-I3 | ... AW25: =AW7-AW3
A26: GBP AUD | B26: =B7-B2 | C26: =C7-C2 | D26: =D7-D2 | E26: =E7-E2 | F26: =F7-F2 | G26: =G7-G2 | H26: =H7-H2 | I26: =I7-I2 | ... AW26: =AW7-AW2
A27: GBP NZD | B27: =B7-B5 | C27: =C7-C5 | D27: =D7-D5 | E27: =E7-E5 | F27: =F7-F5 | G27: =G7-G5 | H27: =H7-H5 | I27: =I7-I5 | ... AW27: =AW7-AW5
A28: CHF JPY | B28: =B6-B4 | C28: =C6-C4 | D28: =D6-D4 | E28: =E6-E4 | F28: =F6-F4 | G28: =G6-G4 | H28: =H6-H4 | I28: =I6-I4 | ... AW28: =AW6-AW4
A29: AUD USD | B29: =B2-B8 | C29: =C2-C8 | D29: =D2-D8 | E29: =E2-E8 | F29: =F2-F8 | G29: =G2-G8 | H29: =H2-H8 | I29: =I2-I8 | ... AW29: =AW2-AW8
A30: AUD CHF | B30: =B2-B6 | C30: =C2-C6 | D30: =D2-D6 | E30: =E2-E6 | F30: =F2-F6 | G30: =G2-G6 | H30: =H2-H6 | I30: =I2-I6 | ... AW30: =AW2-AW6
A31: AUD JPY | B31: =B2-B4 | C31: =C2-C4 | D31: =D2-D4 | E31: =E2-E4 | F31: =F2-F4 | G31: =G2-G4 | H31: =H2-H4 | I31: =I2-I4 | ... AW31: =AW2-AW4
A32: AUD NZD | B32: =B2-B5 | C32: =C2-C5 | D32: =D2-D5 | E32: =E2-E5 | F32: =F2-F5 | G32: =G2-G5 | H32: =H2-H5 | I32: =I2-I5 | ... AW32: =AW2-AW5
A33: AUD CAD | B33: =B2-B3 | C33: =C2-C3 | D33: =D2-D3 | E33: =E2-E3 | F33: =F2-F3 | G33: =G2-G3 | H33: =H2-H3 | I33: =I2-I3 | ... AW33: =AW2-AW3
A34: CAD JPY | B34: =B3-B4 | C34: =C3-C4 | D34: =D3-D4 | E34: =E3-E4 | F34: =F3-F4 | G34: =G3-G4 | H34: =H3-H4 | I34: =I3-I4 | ... AW34: =AW3-AW4
A37: Pair | B37: 44927 | C37: 44958 | D37: 44986 | E37: 45017 | F37: 45047 | G37: 45078 | H37: 45108 | I37: 45139 | J37: 45170 | K37: 45200 | L37: 45231 | M37: 45261 | N37: 45292 | O37: 45323 | P37: 45352 | Q37: 45383 | R37: 45413 | S37: 45444 | T37: 45474 | U37: 45505 | V37: 45536 | W37: 45566 | X37: 45597 | Y37: 45627 | Z37: 45658 | AA37: 45689 | AB37: 45717 | AC37: 45748 | AD37: 45778 | AE37: 45809 | AF37: 45839 | AG37: 45870 | AH37: 45901 | AI37: 45931 | AJ37: 45962 | AK37: 45992 | AL37: 46023 | AM37: 46054 | AN37: 46082 | AO37: 46113 | AP37: 46143 | AQ37: 46174 | AR37: 46204 | AS37: 46235 | AT37: 46266 | AU37: 46296 | AV37: 46327 | AW37: 46357
A38: USD JPY | B38: =VLOOKUP(ROUND(B12, 0), $AY$3:$AZ$13, 2, FALSE) | C38: =VLOOKUP(ROUND(C12, 0), $AY$3:$AZ$13, 2, FALSE) | D38: =VLOOKUP(ROUND(D12, 0), $AY$3:$AZ$13, 2, FALSE) | E38: =VLOOKUP(ROUND(E12, 0), $AY$3:$AZ$13, 2, FALSE) | F38: =VLOOKUP(ROUND(F12, 0), $AY$3:$AZ$13, 2, FALSE) | G38: =VLOOKUP(ROUND(G12, 0), $AY$3:$AZ$13, 2, FALSE) | H38: =VLOOKUP(ROUND(H12, 0), $AY$3:$AZ$13, 2, FALSE) | I38: =VLOOKUP(ROUND(I12, 0), $AY$3:$AZ$13, 2, FALSE) | ... AW38: =VLOOKUP(ROUND(AW12, 0), $AY$3:$AZ$13, 2, FALSE)
A39: USD CHF | B39: =VLOOKUP(ROUND(B13, 0), $AY$3:$AZ$13, 2, FALSE) | C39: =VLOOKUP(ROUND(C13, 0), $AY$3:$AZ$13, 2, FALSE) | D39: =VLOOKUP(ROUND(D13, 0), $AY$3:$AZ$13, 2, FALSE) | E39: =VLOOKUP(ROUND(E13, 0), $AY$3:$AZ$13, 2, FALSE) | F39: =VLOOKUP(ROUND(F13, 0), $AY$3:$AZ$13, 2, FALSE) | G39: =VLOOKUP(ROUND(G13, 0), $AY$3:$AZ$13, 2, FALSE) | H39: =VLOOKUP(ROUND(H13, 0), $AY$3:$AZ$13, 2, FALSE) | I39: =VLOOKUP(ROUND(I13, 0), $AY$3:$AZ$13, 2, FALSE) | ... AW39: =VLOOKUP(ROUND(AW13, 0), $AY$3:$AZ$13, 2, FALSE)
A40: USD CAD | B40: =VLOOKUP(ROUND(B14, 0), $AY$3:$AZ$13, 2, FALSE) | C40: =VLOOKUP(ROUND(C14, 0), $AY$3:$AZ$13, 2, FALSE) | D40: =VLOOKUP(ROUND(D14, 0), $AY$3:$AZ$13, 2, FALSE) | E40: =VLOOKUP(ROUND(E14, 0), $AY$3:$AZ$13, 2, FALSE) | F40: =VLOOKUP(ROUND(F14, 0), $AY$3:$AZ$13, 2, FALSE) | G40: =VLOOKUP(ROUND(G14, 0), $AY$3:$AZ$13, 2, FALSE) | H40: =VLOOKUP(ROUND(H14, 0), $AY$3:$AZ$13, 2, FALSE) | I40: =VLOOKUP(ROUND(I14, 0), $AY$3:$AZ$13, 2, FALSE) | ... AW40: =VLOOKUP(ROUND(AW14, 0), $AY$3:$AZ$13, 2, FALSE)
A41: EUR USD | B41: =VLOOKUP(ROUND(B15, 0), $AY$3:$AZ$13, 2, FALSE) | C41: =VLOOKUP(ROUND(C15, 0), $AY$3:$AZ$13, 2, FALSE) | D41: =VLOOKUP(ROUND(D15, 0), $AY$3:$AZ$13, 2, FALSE) | E41: =VLOOKUP(ROUND(E15, 0), $AY$3:$AZ$13, 2, FALSE) | F41: =VLOOKUP(ROUND(F15, 0), $AY$3:$AZ$13, 2, FALSE) | G41: =VLOOKUP(ROUND(G15, 0), $AY$3:$AZ$13, 2, FALSE) | H41: =VLOOKUP(ROUND(H15, 0), $AY$3:$AZ$13, 2, FALSE) | I41: =VLOOKUP(ROUND(I15, 0), $AY$3:$AZ$13, 2, FALSE) | ... AW41: =VLOOKUP(ROUND(AW15, 0), $AY$3:$AZ$13, 2, FALSE)
A42: EUR JPY | B42: =VLOOKUP(ROUND(B16, 0), $AY$3:$AZ$13, 2, FALSE) | C42: =VLOOKUP(ROUND(C16, 0), $AY$3:$AZ$13, 2, FALSE) | D42: =VLOOKUP(ROUND(D16, 0), $AY$3:$AZ$13, 2, FALSE) | E42: =VLOOKUP(ROUND(E16, 0), $AY$3:$AZ$13, 2, FALSE) | F42: =VLOOKUP(ROUND(F16, 0), $AY$3:$AZ$13, 2, FALSE) | G42: =VLOOKUP(ROUND(G16, 0), $AY$3:$AZ$13, 2, FALSE) | H42: =VLOOKUP(ROUND(H16, 0), $AY$3:$AZ$13, 2, FALSE) | I42: =VLOOKUP(ROUND(I16, 0), $AY$3:$AZ$13, 2, FALSE) | ... AW42: =VLOOKUP(ROUND(AW16, 0), $AY$3:$AZ$13, 2, FALSE)
...

Sheet CA GDP DATA
A2: BOP | B2: 44927 | C2: 44958 | D2: 44986 | E2: 45017 | F2: 45047 | G2: 45078 | H2: 45108 | I2: 45139 | J2: 45170 | K2: 45200 | L2: 45231 | M2: 45261 | N2: 45292 | O2: 45323 | P2: 45352 | Q2: 45383 | R2: 45413 | S2: 45444 | T2: 45474 | U2: 45505 | V2: 45536 | W2: 45566 | X2: 45597 | Y2: 45627 | Z2: 45658 | AA2: 45689 | AB2: 45717 | AC2: 45748 | AD2: 45778 | AE2: 45809 | AF2: 45839 | AG2: 45870 | AH2: 45901 | AI2: 45931 | AJ2: 45962 | AK2: 45992 | AL2: 46023 | AM2: 46054 | AN2: 46082 | AO2: 46113 | AP2: 46143 | AQ2: 46174 | AR2: 46204 | AS2: 46235 | AT2: 46266 | AU2: 46296 | AV2: 46327 | AW2: 46357
A3: Australia | B3: 0.5178161 | C3: 0.5178161 | D3: 0.5178161 | E3: -0.2283273 | F3: -0.2283273 | G3: -0.2283273 | H3: -1.40563 | I3: -1.40563 | J3: -1.40563 | K3: -0.2746948 | L3: -0.2746948 | M3: -0.2746948 | N3: -1.318746 | O3: -1.318746 | P3: -1.318746 | Q3: -2.394648 | R3: -2.394648 | S3: -2.394648 | T3: -2.472772 | U3: -2.472772 | V3: -2.472772 | W3: -2.611136 | X3: -2.611136 | Y3: -2.611136 | Z3: -2.264893 | AA3: -2.264893 | AB3: -2.264893 | AC3: -2.380304 | AD3: -2.380304 | AE3: -2.380304 | AF3: -2.648238 | AG3: -2.648238 | AH3: -2.648238 | AI3: -3.106944 | AJ3: -3.106944 | AK3: -3.106944 | AL3: -3.453962 | AM3: -3.453962 | AN3: -3.453962 | AO3: -3.665983 | AP3: -3.665983 | AQ3: -3.665983 | AR3: -3.665983 | AS3: -3.665983 | AT3: -3.665983
A4: Canada | B4: -0.9103057 | C4: -0.9103057 | D4: -0.9103057 | E4: -0.7758245 | F4: -0.7758245 | G4: -0.7758245 | H4: -0.7987553 | I4: -0.7987553 | J4: -0.7987553 | K4: -0.2814779 | L4: -0.2814779 | M4: -0.2814779 | N4: -0.7692237 | O4: -0.7692237 | P4: -0.7692237 | Q4: -0.4802992 | R4: -0.4802992 | S4: -0.4802992 | T4: -0.5910502 | U4: -0.5910502 | V4: -0.5910502 | W4: -0.1004742 | X4: -0.1004742 | Y4: -0.1004742 | Z4: -0.3616118 | AA4: -0.3616118 | AB4: -0.3616118 | AC4: -2.715445 | AD4: -2.715445 | AE4: -2.715445 | AF4: -0.6209641 | AG4: -0.6209641 | AH4: -0.6209641 | AI4: -0.1228772 | AJ4: -0.1228772 | AK4: -0.1228772 | AL4: -0.9986504 | AM4: -0.9986504 | AN4: -0.9986504 | AO4: 1.028123 | AP4: 1.028123 | AQ4: 1.028123 | AR4: 1.028123 | AS4: 1.028123 | AT4: 1.028123
A5: Japan | B5: 2.198734 | C5: 2.198734 | D5: 2.198734 | E5: 3.925856 | F5: 3.925856 | G5: 3.925856 | H5: 4.356519 | I5: 4.356519 | J5: 4.356519 | K5: 4.297242 | L5: 4.297242 | M5: 4.297242 | N5: 4.324823 | O5: 4.324823 | P5: 4.324823 | Q5: 4.471209 | R5: 4.471209 | S5: 4.471209 | T5: 4.842206 | U5: 4.842206 | V5: 4.842206 | W5: 4.697466 | X5: 4.697466 | Y5: 4.697466 | Z5: 4.628131 | AA5: 4.628131 | AB5: 4.628131 | AC5: 4.412066 | AD5: 4.412066 | AE5: 4.412066 | AF5: 5.328309 | AG5: 5.328309 | AH5: 5.328309 | AI5: 4.902074 | AJ5: 4.902074 | AK5: 4.902074 | AL5: 5.809678 | AM5: 5.809678 | AN5: 5.809678 | AO5: 5.033247 | AP5: 5.033247 | AQ5: 5.033247 | AR5: 5.033247 | AS5: 5.033247 | AT5: 5.033247
A6: Switzerland | B6: 5.051963 | C6: 5.051963 | D6: 5.051963 | E6: 6.851121 | F6: 6.851121 | G6: 6.851121 | H6: 7.81084 | I6: 7.81084 | J6: 7.81084 | K6: 3.0269 | L6: 3.0269 | M6: 3.0269 | N6: 11.87226 | O6: 11.87226 | P6: 11.87226 | Q6: 11.46023 | R6: 11.46023 | S6: 11.46023 | T6: 3.415149 | U6: 3.415149 | V6: 3.415149 | W6: 9.550939 | X6: 9.550939 | Y6: 9.550939 | Z6: 15.59482 | AA6: 15.59482 | AB6: 15.59482 | AC6: 3.399356 | AD6: 3.399356 | AE6: 3.399356 | AF6: 4.245384 | AG6: 4.245384 | AH6: 4.245384 | AI6: 0.1449953 | AJ6: 0.1449953 | AK6: 0.1449953 | AL6: 10.02279 | AM6: 10.02279 | AN6: 10.02279 | AO6: 9.198192 | AP6: 9.198192 | AQ6: 9.198192 | AR6: 9.198192 | AS6: 9.198192 | AT6: 9.198192
A7: New Zealand | B7: -7.207618 | C7: -7.207618 | D7: -7.207618 | E7: -5.753605 | F7: -5.753605 | G7: -5.753605 | H7: -5.886574 | I7: -5.886574 | J7: -5.886574 | K7: -5.338708 | L7: -5.338708 | M7: -5.338708 | N7: -5.368975 | O7: -5.368975 | P7: -5.368975 | Q7: -5.430479 | R7: -5.430479 | S7: -5.430479 | T7: -4.83238 | U7: -4.83238 | V7: -4.83238 | W7: -4.003401 | X7: -4.003401 | Y7: -4.003401 | Z7: -3.545576 | AA7: -3.545576 | AB7: -3.545576 | AC7: -2.391005 | AD7: -2.391005 | AE7: -2.391005 | AF7: -2.354201 | AG7: -2.354201 | AH7: -2.354201 | AI7: -3.647876 | AJ7: -3.647876 | AK7: -3.647876 | AL7: -3.849324 | AM7: -3.849324 | AN7: -3.849324 | AO7: -3.255669 | AP7: -3.255669 | AQ7: -3.255669 | AR7: -3.255669 | AS7: -3.255669 | AT7: -3.255669 | AY7: 14 | AZ7: 10
A8: United Kingdom | B8: -2.913895 | C8: -2.913895 | D8: -2.913895 | E8: -5.029161 | F8: -5.029161 | G8: -5.029161 | H8: -2.271199 | I8: -2.271199 | J8: -2.271199 | K8: -4.062315 | L8: -4.062315 | M8: -4.062315 | N8: -2.972881 | O8: -2.972881 | P8: -2.972881 | Q8: -3.261572 | R8: -3.261572 | S8: -3.261572 | T8: -1.932302 | U8: -1.932302 | V8: -1.932302 | W8: -3.654375 | X8: -3.654375 | Y8: -3.654375 | Z8: -3.101889 | AA8: -3.101889 | AB8: -3.101889 | AC8: -3.238587 | AD8: -3.238587 | AE8: -3.238587 | AF8: -2.634263 | AG8: -2.634263 | AH8: -2.634263 | AI8: -3.541209 | AJ8: -3.541209 | AK8: -3.541209 | AL8: -2.835533 | AM8: -2.835533 | AN8: -2.835533 | AO8: -2.835533 | AP8: -2.835533 | AQ8: -2.835533 | AR8: -2.835533 | AS8: -2.835533 | AT8: -2.835533 | AY8: 12 | AZ8: 9
A9: United States | B9: -3.276534 | C9: -3.276534 | D9: -3.276534 | E9: -3.371748 | F9: -3.371748 | G9: -3.371748 | H9: -3.181111 | I9: -3.181111 | J9: -3.181111 | K9: -3.561928 | L9: -3.561928 | M9: -3.561928 | N9: -3.606222 | O9: -3.606222 | P9: -3.606222 | Q9: -3.882617 | R9: -3.882617 | S9: -3.882617 | T9: -4.48155 | U9: -4.48155 | V9: -4.48155 | W9: -4.375336 | X9: -4.375336 | Y9: -4.375336 | Z9: -5.834996 | AA9: -5.834996 | AB9: -5.834996 | AC9: -3.344384 | AD9: -3.344384 | AE9: -3.344384 | AF9: -3.381205 | AG9: -3.381205 | AH9: -3.381205 | AI9: -2.814096 | AJ9: -2.814096 | AK9: -2.814096 | AL9: -2.668661 | AM9: -2.668661 | AN9: -2.668661 | AO9: -3.029274 | AP9: -3.029274 | AQ9: -3.029274 | AR9: -3.029274 | AS9: -3.029274 | AT9: -3.029274 | AY9: 11 | AZ9: 8
A10: EURO AREA | B10: 0.9049219 | C10: 0.9049219 | D10: 0.9049219 | E10: 1.469623 | F10: 1.469623 | G10: 1.469623 | H10: 1.854201 | I10: 1.854201 | J10: 1.854201 | K10: 2.415108 | L10: 2.415108 | M10: 2.415108 | N10: 2.868217 | O10: 2.868217 | P10: 2.868217 | Q10: 3.068143 | R10: 3.068143 | S10: 3.068143 | T10: 2.158417 | U10: 2.158417 | V10: 2.158417 | W10: 2.027561 | X10: 2.027561 | Y10: 2.027561 | Z10: 1.647232 | AA10: 1.647232 | AB10: 1.647232 | AC10: 1.952547 | AD10: 1.952547 | AE10: 1.952547 | AF10: 1.41954 | AG10: 1.41954 | AH10: 1.41954 | AI10: 1.554832 | AJ10: 1.554832 | AK10: 1.554832 | AL10: 1.917209 | AM10: 1.917209 | AN10: 1.917209 | AO10: 1.917209 | AP10: 1.917209 | AQ10: 1.917209 | AR10: 1.917209 | AS10: 1.917209 | AT10: 1.917209 | AY10: 10 | AZ10: 7
AY11: 9 | AZ11: 6
AX12: 8 | AY12: 8 | AZ12: 5
AY13: 7 | AZ13: 4
A14: Paire | B14: 44927 | C14: 44958 | D14: 44986 | E14: 45017 | F14: 45047 | G14: 45078 | H14: 45108 | I14: 45139 | J14: 45170 | K14: 45200 | L14: 45231 | M14: 45261 | N14: 45292 | O14: 45323 | P14: 45352 | Q14: 45383 | R14: 45413 | S14: 45444 | T14: 45474 | U14: 45505 | V14: 45536 | W14: 45566 | X14: 45597 | Y14: 45627 | Z14: 45658 | AA14: 45689 | AB14: 45717 | AC14: 45748 | AD14: 45778 | AE14: 45809 | AF14: 45839 | AG14: 45870 | AH14: 45901 | AI14: 45931 | AJ14: 45962 | AK14: 45992 | AL14: 46023 | AM14: 46054 | AN14: 46082 | AO14: 46113 | AP14: 46143 | AQ14: 46174 | AR14: 46204 | AS14: 46235 | AT14: 46266 | AU14: 46296 | AV14: 46327 | AW14: 46357 | AY14: 6 | AZ14: 3
A15: USD JPY | B15: =B9-B5 | C15: =C9-C5 | D15: =D9-D5 | E15: =E9-E5 | F15: =F9-F5 | G15: =G9-G5 | H15: =H9-H5 | I15: =I9-I5 | ... AW15: =AW9-AW5 | AY15: 4 | AZ15: 2
A16: USD CHF | B16: =B9-B6 | C16: =C9-C6 | D16: =D9-D6 | E16: =E9-E6 | F16: =F9-F6 | G16: =G9-G6 | H16: =H9-H6 | I16: =I9-I6 | ... AJ16: =AJ9-AJ6 | AK16: =AK10-AK6 | AL16: =AL10-AL6 | AM16: =AM10-AM6 | AN16: =AN10-AN6 | AO16: =AO10-AO6 | AP16: =AP10-AP6 | AQ16: =AQ10-AQ6 | AR16: =AR10-AR6 | ... AW16: =AW10-AW6 | AY16: 2 | AZ16: 1
A17: USD CAD | B17: =B9-B4 | C17: =C9-C4 | D17: =D9-D4 | E17: =E9-E4 | F17: =F9-F4 | G17: =G9-G4 | H17: =H9-H4 | I17: =I9-I4 | ... AW17: =AW9-AW4 | AY17: 0 | AZ17: 0
A18: EUR USD | B18: =B10-B9 | C18: =C10-C9 | D18: =D10-D9 | E18: =E10-E9 | F18: =F10-F9 | G18: =G10-G9 | H18: =H10-H9 | I18: =I10-I9 | ... AW18: =AW10-AW9 | AY18: -2 | AZ18: -1
A19: EUR JPY | B19: =B10-B5 | C19: =C10-C5 | D19: =D10-D5 | E19: =E10-E5 | F19: =F10-F5 | G19: =G10-G5 | H19: =H10-H5 | I19: =I10-I5 | ... AW19: =AW10-AW5 | AY19: -4 | AZ19: -2
A20: EUR CHF | B20: =B10-B6 | C20: =C10-C6 | D20: =D10-D6 | E20: =E10-E6 | F20: =F10-F6 | G20: =G10-G6 | H20: =H10-H6 | I20: =I10-I6 | ... AW20: =AW10-AW6 | AY20: -6 | AZ20: -3
A21: EUR GBP | B21: =B10-B8 | C21: =C10-C8 | D21: =D10-D8 | E21: =E10-E8 | F21: =F10-F8 | G21: =G10-G8 | H21: =H10-H8 | I21: =I10-I8 | ... AW21: =AW10-AW8 | AY21: -7 | AZ21: -4
A22: EUR CAD | B22: =B10-B4 | C22: =C10-C4 | D22: =D10-D4 | E22: =E10-E4 | F22: =F10-F4 | G22: =G10-G4 | H22: =H10-H4 | I22: =I10-I4 | ... AW22: =AW10-AW4 | AY22: -8 | AZ22: -5
A23: EUR AUD | B23: 0 | C23: 0 | D23: 0 | E23: 0 | F23: 0 | G23: 0 | H23: 0 | I23: 0 | J23: 0 | K23: 0 | L23: 0 | M23: 0 | N23: 0 | O23: 0 | P23: 0 | Q23: 0 | R23: 0 | S23: 0 | T23: 0 | U23: 0 | V23: 0 | W23: 0 | X23: 0 | Y23: 0 | Z23: 0 | AA23: 0 | AB23: 0 | AC23: =AC10-AC3 | AD23: =AD10-AD3 | AE23: =AE10-AE3 | AF23: =AF10-AF3 | AG23: =AG10-AG3 | AH23: =AH10-AH3 | AI23: =AI10-AI3 | AJ23: =AJ10-AJ3 | ... AW23: =AW10-AW3 | AY23: -9 | AZ23: -6
A24: EUR NZD | B24: =B10-B7 | C24: =C10-C7 | D24: =D10-D7 | E24: =E10-E7 | F24: =F10-F7 | G24: =G10-G7 | H24: =H10-H7 | I24: =I10-I7 | ... AW24: =AW10-AW7 | AY24: -10 | AZ24: -7
A25: GBP USD | B25: =B8-B9 | C25: =C8-C9 | D25: =D8-D9 | E25: =E8-E9 | F25: =F8-F9 | G25: =G8-G9 | H25: =H8-H9 | I25: =I8-I9 | ... AW25: =AW8-AW9 | AY25: -11 | AZ25: -8
A26: GBP JPY | B26: =B8-B5 | C26: =C8-C5 | D26: =D8-D5 | E26: =E8-E5 | F26: =F8-F5 | G26: =G8-G5 | H26: =H8-H5 | I26: =I8-I5 | ... AW26: =AW8-AW5 | AY26: -12 | AZ26: -9
A27: GBP CHF | B27: =B8-B6 | C27: =C8-C6 | D27: =D8-D6 | E27: =E8-E6 | F27: =F8-F6 | G27: =G8-G6 | H27: =H8-H6 | I27: =I8-I6 | ... AW27: =AW8-AW6 | AY27: -14 | AZ27: -10
A28: GBP CAD | B28: =B8-B4 | C28: =C8-C4 | D28: =D8-D4 | E28: =E8-E4 | F28: =F8-F4 | G28: =G8-G4 | H28: =H8-H4 | I28: =I8-I4 | ... AW28: =AW8-AW4
A29: GBP AUD | B29: =B8-B3 | C29: =C8-C3 | D29: =D8-D3 | E29: =E8-E3 | F29: =F8-F3 | G29: =G8-G3 | H29: =H8-H3 | I29: =I8-I3 | ... AW29: =AW8-AW3
A30: GBP NZD | B30: =B8-B7 | C30: =C8-C7 | D30: =D8-D7 | E30: =E8-E7 | F30: =F8-F7 | G30: =G8-G7 | H30: =H8-H7 | I30: =I8-I7 | ... AW30: =AW8-AW7
A31: CHF JPY | B31: =B6-B5 | C31: =C6-C5 | D31: =D6-D5 | E31: =E6-E5 | F31: =F6-F5 | G31: =G6-G5 | H31: =H6-H5 | I31: =I6-I5 | ... AW31: =AW6-AW5
A32: AUD USD | B32: =B3-B9 | C32: =C3-C9 | D32: =D3-D9 | E32: =E3-E9 | F32: =F3-F9 | G32: =G3-G9 | H32: =H3-H9 | I32: =I3-I9 | ... AW32: =AW3-AW9
A33: AUD CHF | B33: =B3-B6 | C33: =C3-C6 | D33: =D3-D6 | E33: =E3-E6 | F33: =F3-F6 | G33: =G3-G6 | H33: =H3-H6 | I33: =I3-I6 | ... AW33: =AW3-AW6
A34: AUD JPY | B34: =B3-B5 | C34: =C3-C5 | D34: =D3-D5 | E34: =E3-E5 | F34: =F3-F5 | G34: =G3-G5 | H34: =H3-H5 | I34: =I3-I5 | ... AW34: =AW3-AW5
A35: AUD NZD | B35: =B3-B7 | C35: =C3-C7 | D35: =D3-D7 | E35: =E3-E7 | F35: =F3-F7 | G35: =G3-G7 | H35: =H3-H7 | I35: =I3-I7 | ... AW35: =AW3-AW7
A36: AUD CAD | B36: =B3-B4 | C36: =C3-C4 | D36: =D3-D4 | E36: =E3-E4 | F36: =F3-F4 | G36: =G3-G4 | H36: =H3-H4 | I36: =I3-I4 | ... AW36: =AW3-AW4
A37: CAD JPY | B37: =B4-B5 | C37: =C4-C5 | D37: =D4-D5 | E37: =E4-E5 | F37: =F4-F5 | G37: =G4-G5 | H37: =H4-H5 | I37: =I4-I5 | ... AW37: =AW4-AW5
A43: Paire | B43: 44927 | C43: 44958 | D43: 44986 | E43: 45017 | F43: 45047 | G43: 45078 | H43: 45108 | I43: 45139 | J43: 45170 | K43: 45200 | L43: 45231 | M43: 45261 | N43: 45292 | O43: 45323 | P43: 45352 | Q43: 45383 | R43: 45413 | S43: 45444 | T43: 45474 | U43: 45505 | V43: 45536 | W43: 45566 | X43: 45597 | Y43: 45627 | Z43: 45658 | AA43: 45689 | AB43: 45717 | AC43: 45748 | AD43: 45778 | AE43: 45809 | AF43: 45839 | AG43: 45870 | AH43: 45901 | AI43: 45931 | AJ43: 45962 | AK43: 45992 | AL43: 46023 | AM43: 46054 | AN43: 46082 | AO43: 46113 | AP43: 46143 | AQ43: 46174 | AR43: 46204 | AS43: 46235 | AT43: 46266 | AU43: 46296 | AV43: 46327 | AW43: 46357
A44: USD JPY | B44: {=_xlfn.XLOOKUP(MIN(ABS($AY$7:$AY$27 - MEDIAN(MIN($AY$7:$AY$27), MAX($AY$7:$AY$27), B15))), ABS($AY$7:$AY$27 - MEDIAN(MIN($AY$7:$AY$27), MAX($AY$7:$AY$27), B15)), $AZ$7:$AZ$27, "Not Found", 0)} | C44: {=_xlfn.XLOOKUP(MIN(ABS($AY$7:$AY$27 - MEDIAN(MIN($AY$7:$AY$27), MAX($AY$7:$AY$27), C15))), ABS($AY$7:$AY$27 - MEDIAN(MIN($AY$7:$AY$27), MAX($AY$7:$AY$27), C15)), $AZ$7:$AZ$27, "Not Found", 0)} | D44: {=_xlfn.XLOOKUP(MIN(ABS($AY$7:$AY$27 - MEDIAN(MIN($AY$7:$AY$27), MAX($AY$7:$AY$27), D15))), ABS($AY$7:$AY$27 - MEDIAN(MIN($AY$7:$AY$27), MAX($AY$7:$AY$27), D15)), $AZ$7:$AZ$27, "Not Found", 0)} | E44: {=_xlfn.XLOOKUP(MIN(ABS($AY$7:$AY$27 - MEDIAN(MIN($AY$7:$AY$27), MAX($AY$7:$AY$27), E15))), ABS($AY$7:$AY$27 - MEDIAN(MIN($AY$7:$AY$27), MAX($AY$7:$AY$27), E15)), $AZ$7:$AZ$27, "Not Found", 0)} | F44: {=_xlfn.XLOOKUP(MIN(ABS($AY$7:$AY$27 - MEDIAN(MIN($AY$7:$AY$27), MAX($AY$7:$AY$27), F15))), ABS($AY$7:$AY$27 - MEDIAN(MIN($AY$7:$AY$27), MAX($AY$7:$AY$27), F15)), $AZ$7:$AZ$27, "Not Found", 0)} | G44: {=_xlfn.XLOOKUP(MIN(ABS($AY$7:$AY$27 - MEDIAN(MIN($AY$7:$AY$27), MAX($AY$7:$AY$27), G15))), ABS($AY$7:$AY$27 - MEDIAN(MIN($AY$7:$AY$27), MAX($AY$7:$AY$27), G15)), $AZ$7:$AZ$27, "Not Found", 0)} | H44: {=_xlfn.XLOOKUP(MIN(ABS($AY$7:$AY$27 - MEDIAN(MIN($AY$7:$AY$27), MAX($AY$7:$AY$27), H15))), ABS($AY$7:$AY$27 - MEDIAN(MIN($AY$7:$AY$27), MAX($AY$7:$AY$27), H15)), $AZ$7:$AZ$27, "Not Found", 0)} | I44: {=_xlfn.XLOOKUP(MIN(ABS($AY$7:$AY$27 - MEDIAN(MIN($AY$7:$AY$27), MAX($AY$7:$AY$27), I15))), ABS($AY$7:$AY$27 - MEDIAN(MIN($AY$7:$AY$27), MAX($AY$7:$AY$27), I15)), $AZ$7:$AZ$27, "Not Found", 0)} | ... AW44: {=_xlfn.XLOOKUP(MIN(ABS($AY$7:$AY$27 - MEDIAN(MIN($AY$7:$AY$27), MAX($AY$7:$AY$27), AW15))), ABS($AY$7:$AY$27 - MEDIAN(MIN($AY$7:$AY$27), MAX($AY$7:$AY$27), AW15)), $AZ$7:$AZ$27, "Not Found", 0)}
A45: USD CHF | B45: {=_xlfn.XLOOKUP(MIN(ABS($AY$7:$AY$27 - MEDIAN(MIN($AY$7:$AY$27), MAX($AY$7:$AY$27), B16))), ABS($AY$7:$AY$27 - MEDIAN(MIN($AY$7:$AY$27), MAX($AY$7:$AY$27), B16)), $AZ$7:$AZ$27, "Not Found", 0)} | C45: {=_xlfn.XLOOKUP(MIN(ABS($AY$7:$AY$27 - MEDIAN(MIN($AY$7:$AY$27), MAX($AY$7:$AY$27), C16))), ABS($AY$7:$AY$27 - MEDIAN(MIN($AY$7:$AY$27), MAX($AY$7:$AY$27), C16)), $AZ$7:$AZ$27, "Not Found", 0)} | D45: {=_xlfn.XLOOKUP(MIN(ABS($AY$7:$AY$27 - MEDIAN(MIN($AY$7:$AY$27), MAX($AY$7:$AY$27), D16))), ABS($AY$7:$AY$27 - MEDIAN(MIN($AY$7:$AY$27), MAX($AY$7:$AY$27), D16)), $AZ$7:$AZ$27, "Not Found", 0)} | E45: {=_xlfn.XLOOKUP(MIN(ABS($AY$7:$AY$27 - MEDIAN(MIN($AY$7:$AY$27), MAX($AY$7:$AY$27), E16))), ABS($AY$7:$AY$27 - MEDIAN(MIN($AY$7:$AY$27), MAX($AY$7:$AY$27), E16)), $AZ$7:$AZ$27, "Not Found", 0)} | F45: {=_xlfn.XLOOKUP(MIN(ABS($AY$7:$AY$27 - MEDIAN(MIN($AY$7:$AY$27), MAX($AY$7:$AY$27), F16))), ABS($AY$7:$AY$27 - MEDIAN(MIN($AY$7:$AY$27), MAX($AY$7:$AY$27), F16)), $AZ$7:$AZ$27, "Not Found", 0)} | G45: {=_xlfn.XLOOKUP(MIN(ABS($AY$7:$AY$27 - MEDIAN(MIN($AY$7:$AY$27), MAX($AY$7:$AY$27), G16))), ABS($AY$7:$AY$27 - MEDIAN(MIN($AY$7:$AY$27), MAX($AY$7:$AY$27), G16)), $AZ$7:$AZ$27, "Not Found", 0)} | H45: {=_xlfn.XLOOKUP(MIN(ABS($AY$7:$AY$27 - MEDIAN(MIN($AY$7:$AY$27), MAX($AY$7:$AY$27), H16))), ABS($AY$7:$AY$27 - MEDIAN(MIN($AY$7:$AY$27), MAX($AY$7:$AY$27), H16)), $AZ$7:$AZ$27, "Not Found", 0)} | I45: {=_xlfn.XLOOKUP(MIN(ABS($AY$7:$AY$27 - MEDIAN(MIN($AY$7:$AY$27), MAX($AY$7:$AY$27), I16))), ABS($AY$7:$AY$27 - MEDIAN(MIN($AY$7:$AY$27), MAX($AY$7:$AY$27), I16)), $AZ$7:$AZ$27, "Not Found", 0)} | ... AW45: {=_xlfn.XLOOKUP(MIN(ABS($AY$7:$AY$27 - MEDIAN(MIN($AY$7:$AY$27), MAX($AY$7:$AY$27), AW16))), ABS($AY$7:$AY$27 - MEDIAN(MIN($AY$7:$AY$27), MAX($AY$7:$AY$27), AW16)), $AZ$7:$AZ$27, "Not Found", 0)}
A46: USD CAD | B46: {=_xlfn.XLOOKUP(MIN(ABS($AY$7:$AY$27 - MEDIAN(MIN($AY$7:$AY$27), MAX($AY$7:$AY$27), B17))), ABS($AY$7:$AY$27 - MEDIAN(MIN($AY$7:$AY$27), MAX($AY$7:$AY$27), B17)), $AZ$7:$AZ$27, "Not Found", 0)} | C46: {=_xlfn.XLOOKUP(MIN(ABS($AY$7:$AY$27 - MEDIAN(MIN($AY$7:$AY$27), MAX($AY$7:$AY$27), C17))), ABS($AY$7:$AY$27 - MEDIAN(MIN($AY$7:$AY$27), MAX($AY$7:$AY$27), C17)), $AZ$7:$AZ$27, "Not Found", 0)} | D46: {=_xlfn.XLOOKUP(MIN(ABS($AY$7:$AY$27 - MEDIAN(MIN($AY$7:$AY$27), MAX($AY$7:$AY$27), D17))), ABS($AY$7:$AY$27 - MEDIAN(MIN($AY$7:$AY$27), MAX($AY$7:$AY$27), D17)), $AZ$7:$AZ$27, "Not Found", 0)} | E46: {=_xlfn.XLOOKUP(MIN(ABS($AY$7:$AY$27 - MEDIAN(MIN($AY$7:$AY$27), MAX($AY$7:$AY$27), E17))), ABS($AY$7:$AY$27 - MEDIAN(MIN($AY$7:$AY$27), MAX($AY$7:$AY$27), E17)), $AZ$7:$AZ$27, "Not Found", 0)} | F46: {=_xlfn.XLOOKUP(MIN(ABS($AY$7:$AY$27 - MEDIAN(MIN($AY$7:$AY$27), MAX($AY$7:$AY$27), F17))), ABS($AY$7:$AY$27 - MEDIAN(MIN($AY$7:$AY$27), MAX($AY$7:$AY$27), F17)), $AZ$7:$AZ$27, "Not Found", 0)} | G46: {=_xlfn.XLOOKUP(MIN(ABS($AY$7:$AY$27 - MEDIAN(MIN($AY$7:$AY$27), MAX($AY$7:$AY$27), G17))), ABS($AY$7:$AY$27 - MEDIAN(MIN($AY$7:$AY$27), MAX($AY$7:$AY$27), G17)), $AZ$7:$AZ$27, "Not Found", 0)} | H46: {=_xlfn.XLOOKUP(MIN(ABS($AY$7:$AY$27 - MEDIAN(MIN($AY$7:$AY$27), MAX($AY$7:$AY$27), H17))), ABS($AY$7:$AY$27 - MEDIAN(MIN($AY$7:$AY$27), MAX($AY$7:$AY$27), H17)), $AZ$7:$AZ$27, "Not Found", 0)} | I46: {=_xlfn.XLOOKUP(MIN(ABS($AY$7:$AY$27 - MEDIAN(MIN($AY$7:$AY$27), MAX($AY$7:$AY$27), I17))), ABS($AY$7:$AY$27 - MEDIAN(MIN($AY$7:$AY$27), MAX($AY$7:$AY$27), I17)), $AZ$7:$AZ$27, "Not Found", 0)} | ... AW46: {=_xlfn.XLOOKUP(MIN(ABS($AY$7:$AY$27 - MEDIAN(MIN($AY$7:$AY$27), MAX($AY$7:$AY$27), AW17))), ABS($AY$7:$AY$27 - MEDIAN(MIN($AY$7:$AY$27), MAX($AY$7:$AY$27), AW17)), $AZ$7:$AZ$27, "Not Found", 0)}
...

Sheet CPI data
A2: CPI %YoY - source : IMF | B2: 44927 | C2: 44958 | D2: 44986 | E2: 45017 | F2: 45047 | G2: 45078 | H2: 45108 | I2: 45139 | J2: 45170 | K2: 45200 | L2: 45231 | M2: 45261 | N2: 45292 | O2: 45323 | P2: 45352 | Q2: 45383 | R2: 45413 | S2: 45444 | T2: 45474 | U2: 45505 | V2: 45536 | W2: 45566 | X2: 45597 | Y2: 45627 | Z2: 45658 | AA2: 45689 | AB2: 45717 | AC2: 45748 | AD2: 45778 | AE2: 45809 | AF2: 45839 | AG2: 45870 | AH2: 45901 | AI2: 45931 | AJ2: 45962 | AK2: 45992 | AL2: 46023 | AM2: 46054 | AN2: 46082 | AO2: 46113 | AP2: 46143 | AQ2: 46174 | AR2: 46204 | AS2: 46235 | AT2: 46266 | AU2: 46296 | AV2: 46327 | AW2: 46357
A3: Australia | B3: 7.5 | C3: 6.8 | D3: 6.3 | E3: 6.7 | F3: 5.5 | G3: 5.4 | H3: 4.9 | I3: 5.2 | J3: 5.6 | K3: 4.9 | L3: 4.3 | M3: 3.4 | N3: 3.4 | O3: 3.4 | P3: 3.5 | Q3: 3.6 | R3: 4 | S3: 3.8 | T3: 3.5 | U3: 2.7 | V3: 2.1 | W3: 2.1 | X3: 2.4 | Y3: 2.4 | Z3: 2.4 | AA3: 2.4 | AB3: 2.4 | AC3: 2.4 | AD3: 2.1 | AE3: 1.9 | AF3: 3 | AG3: 3.2 | AH3: 3.6 | AI3: 3.8 | AJ3: 3.4 | AK3: 3.8 | AL3: 3.8 | AM3: 3.7 | AN3: 4.6 | AO3: 4.2 | AP3: 4 | AQ3: 3.8 | AR3: 3.5 | AS3: 4 | AT3: 4.1 | AU3: 4.2
A4: Canada | B4: 5.9 | C4: 5.2 | D4: 4.3 | E4: 4.4 | F4: 3.4 | G4: 2.8 | H4: 3.3 | I4: 4 | J4: 3.8 | K4: 3.1 | L4: 3.1 | M4: 3.4 | N4: 2.9 | O4: 2.8 | P4: 2.9 | Q4: 2.7 | R4: 2.9 | S4: 2.7 | T4: 2.5 | U4: 2 | V4: 1.6 | W4: 2 | X4: 1.9 | Y4: 1.8 | Z4: 1.9 | AA4: 2.6 | AB4: 2.3 | AC4: 1.7 | AD4: 1.7 | AE4: 1.9 | AF4: 1.7 | AG4: 1.9 | AH4: 2.4 | AI4: 2.2 | AJ4: 2.2 | AK4: 2.4 | AL4: 2.3 | AM4: 1.8 | AN4: 2.4 | AO4: 2.8 | AP4: 3.2 | AQ4: 2.8 | AR4: 3 | AS4: 2.9 | AT4: 2.9 | AU4: 2.6
A5: Japan | B5: 4.3 | C5: 3.3 | D5: 3.2 | E5: 3.5 | F5: 3.2 | G5: 3.3 | H5: 3.3 | I5: 3.2 | J5: 3 | K5: 3.3 | L5: 2.8 | M5: 2.6 | N5: 2.2 | O5: 2.8 | P5: 2.7 | Q5: 2.5 | R5: 2.8 | S5: 2.8 | T5: 2.8 | U5: 3 | V5: 2.5 | W5: 2.3 | X5: 2.9 | Y5: 3.6 | Z5: 4 | AA5: 3.7 | AB5: 3.6 | AC5: 3.6 | AD5: 3.5 | AE5: 3.3 | AF5: 3.1 | AG5: 2.7 | AH5: 2.9 | AI5: 3 | AJ5: 2.9 | AK5: 2.1 | AL5: 1.5 | AM5: 1.3 | AN5: 1.5 | AO5: 1.4 | AP5: 1.5 | AQ5: 1.6 | AR5: 1.9 | AS5: 1.8 | AT5: 1.8 | AU5: 1.8
A6: Switzerland | B6: 3.3 | C6: 3.4 | D6: 2.9 | E6: 2.6 | F6: 2.2 | G6: 1.7 | H6: 1.6 | I6: 1.6 | J6: 1.7 | K6: 1.7 | L6: 1.4 | M6: 1.7 | N6: 1.3 | O6: 1.2 | P6: 1 | Q6: 1.4 | R6: 1.4 | S6: 1.3 | T6: 1.3 | U6: 1.1 | V6: 0.8 | W6: 0.6 | X6: 0.7 | Y6: 0.6 | Z6: 0.4 | AA6: 0.3 | AB6: 0.3 | AC6: 0 | AD6: -0.1 | AE6: 0.1 | AF6: 0.2 | AG6: 0.2 | AH6: 0.2 | AI6: 0.1 | AJ6: 0 | AK6: 0.1 | AL6: 0.1 | AM6: 0.1 | AN6: 0.3 | AO6: 0.6 | AP6: 0.6 | AQ6: 0.5 | AR6: 0.4 | AS6: 0.8 | AT6: 0.8 | AU6: 0.7 | AY6: -2 | AZ6: 2 | BB6: fx pair | BC6: data | BD6: rating | BF6: -0.02 | BG6: 2
A7: New Zealand | B7: 6.7 | C7: 6.7 | D7: 6.7 | E7: 6 | F7: 6 | G7: 6 | H7: 5.6 | I7: 5.6 | J7: 5.6 | K7: 4.7 | L7: 4.7 | M7: 4.7 | N7: 4 | O7: 4 | P7: 4 | Q7: 3.3 | R7: 3.3 | S7: 3.3 | T7: 2.2 | U7: 2.2 | V7: 2.2 | W7: 2.2 | X7: 2.2 | Y7: 2.2 | Z7: 2.5 | AA7: 2.5 | AB7: 2.5 | AC7: 2.7 | AD7: 2.7 | AE7: 2.7 | AF7: 3 | AG7: 3 | AH7: 3 | AI7: 3.1 | AJ7: 3.1 | AK7: 3.1 | AL7: 3.1 | AM7: 3.1 | AN7: 3.1 | AO7: 4.1 | AP7: 4.1 | AQ7: 4.1 | AR7: 3.7 | AS7: 3.7 | AT7: 3.7 | AU7: 3.5 | AY7: -1.75 | AZ7: 3 | BB7: USD JPY | BC7: =AL15 | BD7: -10 | BE7: {=_xlfn.XLOOKUP(MIN(ABS($AY$6:$AY$22 - MEDIAN(-2, 2, BC7))), ABS($AY$6:$AY$22 - MEDIAN(-2, 2, BC7)), $AZ$6:$AZ$22, "Error", 0)} | BF7: -0.0175 | BG7: 3 | BH7: =BD7-BE7
A8: United Kingdom | B8: 10.1 | C8: 10.4 | D8: 10.1 | E8: 8.7 | F8: 8.7 | G8: 7.9 | H8: 6.8 | I8: 6.7 | J8: 6.7 | K8: 4.6 | L8: 3.9 | M8: 4 | N8: 4 | O8: 3.4 | P8: 3.2 | Q8: 2.3 | R8: 2 | S8: 2 | T8: 2.2 | U8: 2.2 | V8: 1.7 | W8: 2.3 | X8: 2.6 | Y8: 2.5 | Z8: 3 | AA8: 2.8 | AB8: 2.6 | AC8: 3.5 | AD8: 3.4 | AE8: 3.6 | AF8: 3.8 | AG8: 3.8 | AH8: 3.8 | AI8: 3.6 | AJ8: 3.2 | AK8: 3.4 | AL8: 3 | AM8: 3 | AN8: 3.3 | AO8: 2.8 | AP8: 2.8 | AQ8: 2.6 | AR8: 2.9 | AS8: 2.9 | AT8: 3.6 | AU8: 3.5 | AY8: -1.5 | AZ8: 4 | BB8: USD CHF | BC8: =AL16 | BD8: 10 | BE8: {=_xlfn.XLOOKUP(MIN(ABS($AY$6:$AY$22 - MEDIAN(-2, 2, BC8))), ABS($AY$6:$AY$22 - MEDIAN(-2, 2, BC8)), $AZ$6:$AZ$22, "Error", 0)} | BF8: -0.015 | BG8: 4 | BH8: =BD8-BE8
A9: United States | B9: 6.4 | C9: 6 | D9: 5 | E9: 4.9 | F9: 4.1 | G9: 3 | H9: 3.2 | I9: 3.7 | J9: 3.7 | K9: 3.2 | L9: 3.1 | M9: 3.4 | N9: 3.1 | O9: 3.2 | P9: 3.5 | Q9: 3.4 | R9: 3.3 | S9: 3 | T9: 2.9 | U9: 2.5 | V9: 2.4 | W9: 2.6 | X9: 2.7 | Y9: 2.9 | Z9: 3 | AA9: 2.8 | AB9: 2.4 | AC9: 2.3 | AD9: 2.4 | AE9: 2.7 | AF9: 2.7 | AG9: 2.9 | AH9: 3 | AI9: 2.7 | AJ9: 2.7 | AK9: 2.7 | AL9: 2.4 | AM9: 2.4 | AN9: 3.3 | AO9: 3.8 | AP9: 4.2 | AQ9: 3.5 | AR9: 3.4 | AS9: 3.7 | AT9: 3.7 | AU9: 3.4 | AY9: -1.25 | AZ9: 6 | BB9: USD CAD | BC9: =AL17 | BD9: 0 | BE9: {=_xlfn.XLOOKUP(MIN(ABS($AY$6:$AY$22 - MEDIAN(-2, 2, BC9))), ABS($AY$6:$AY$22 - MEDIAN(-2, 2, BC9)), $AZ$6:$AZ$22, "Error", 0)} | BF9: -0.0125 | BG9: 6 | BH9: =BD9-BE9
A10: EURO AREA | B10: 8.7 | C10: 8.5 | D10: 6.9 | E10: 7 | F10: 6.1 | G10: 5.5 | H10: 5.3 | I10: 5.2 | J10: 4.3 | K10: 2.9 | L10: 2.4 | M10: 2.9 | N10: 2.8 | O10: 2.6 | P10: 2.4 | Q10: 2.4 | R10: 2.6 | S10: 2.5 | T10: 2.6 | U10: 2.2 | V10: 1.7 | W10: 2 | X10: 2.2 | Y10: 2.4 | Z10: 2.5 | AA10: 2.3 | AB10: 2.2 | AC10: 2.2 | AD10: 1.9 | AE10: 2 | AF10: 2 | AG10: 2 | AH10: 2.2 | AI10: 2.1 | AJ10: 2.1 | AK10: 2 | AL10: 1.7 | AM10: 1.9 | AN10: 2.6 | AO10: 3 | AP10: 3.2 | AQ10: 2.8 | AR10: 2.9 | AS10: 3.3 | AT10: 3.5 | AU10: 3.3 | AY10: -1 | AZ10: 10 | BB10: EUR USD | BC10: =AL18 | BD10: 8 | BE10: {=_xlfn.XLOOKUP(MIN(ABS($AY$6:$AY$22 - MEDIAN(-2, 2, BC10))), ABS($AY$6:$AY$22 - MEDIAN(-2, 2, BC10)), $AZ$6:$AZ$22, "Error", 0)} | BF10: -0.01 | BG10: 10 | BH10: =BD10-BE10
AY11: -0.75 | AZ11: 8 | BB11: EUR JPY | BC11: =AL19 | BD11: -4 | BE11: {=_xlfn.XLOOKUP(MIN(ABS($AY$6:$AY$22 - MEDIAN(-2, 2, BC11))), ABS($AY$6:$AY$22 - MEDIAN(-2, 2, BC11)), $AZ$6:$AZ$22, "Error", 0)} | BF11: -0.0075 | BG11: 8 | BH11: =BD11-BE11
AY12: -0.5 | AZ12: 6 | BB12: EUR CHF | BC12: =AL20 | BD12: 8 | BE12: {=_xlfn.XLOOKUP(MIN(ABS($AY$6:$AY$22 - MEDIAN(-2, 2, BC12))), ABS($AY$6:$AY$22 - MEDIAN(-2, 2, BC12)), $AZ$6:$AZ$22, "Error", 0)} | BF12: -0.005 | BG12: 6 | BH12: =BD12-BE12 | BK12: 8
AY13: -0.25 | AZ13: 4 | BB13: EUR GBP | BC13: =AL21 | BD13: 6 | BE13: {=_xlfn.XLOOKUP(MIN(ABS($AY$6:$AY$22 - MEDIAN(-2, 2, BC13))), ABS($AY$6:$AY$22 - MEDIAN(-2, 2, BC13)), $AZ$6:$AZ$22, "Error", 0)} | BF13: -0.0025 | BG13: 4 | BH13: =BD13-BE13
A14: Paire | B14: 44927 | C14: 44958 | D14: 44986 | E14: 45017 | F14: 45047 | G14: 45078 | H14: 45108 | I14: 45139 | J14: 45170 | K14: 45200 | L14: 45231 | M14: 45261 | N14: 45292 | O14: 45323 | P14: 45352 | Q14: 45383 | R14: 45413 | S14: 45444 | T14: 45474 | U14: 45505 | V14: 45536 | W14: 45566 | X14: 45597 | Y14: 45627 | Z14: 45658 | AA14: 45689 | AB14: 45717 | AC14: 45748 | AD14: 45778 | AE14: 45809 | AF14: 45839 | AG14: 45870 | AH14: 45901 | AI14: 45931 | AJ14: 45962 | AK14: 45992 | AL14: 46023 | AM14: 46054 | AN14: 46082 | AO14: 46113 | AP14: 46143 | AQ14: 46174 | AR14: 46204 | AS14: 46235 | AT14: 46266 | AU14: 46296 | AV14: 46327 | AW14: 46357 | AY14: 0 | AZ14: 0 | BB14: EUR CAD | BC14: =AL22 | BD14: 6 | BE14: {=_xlfn.XLOOKUP(MIN(ABS($AY$6:$AY$22 - MEDIAN(-2, 2, BC14))), ABS($AY$6:$AY$22 - MEDIAN(-2, 2, BC14)), $AZ$6:$AZ$22, "Error", 0)} | BF14: 0 | BG14: 0 | BH14: =BD14-BE14
A15: USD JPY | B15: =B9-B5 | C15: =C9-C5 | D15: =D9-D5 | E15: =E9-E5 | F15: =F9-F5 | G15: =G9-G5 | H15: =H9-H5 | I15: =I9-I5 | ... AW15: =AW9-AW5 | AY15: 0.25 | AZ15: -4 | BB15: EUR AUD | BC15: =AL23 | BD15: 2 | BE15: {=_xlfn.XLOOKUP(MIN(ABS($AY$6:$AY$22 - MEDIAN(-2, 2, BC15))), ABS($AY$6:$AY$22 - MEDIAN(-2, 2, BC15)), $AZ$6:$AZ$22, "Error", 0)} | BF15: 0.0025 | BG15: -4 | BH15: =BD15-BE15
A16: USD CHF | B16: =B9-B6 | C16: =C9-C6 | D16: =D9-D6 | E16: =E9-E6 | F16: =F9-F6 | G16: =G9-G6 | H16: =H9-H6 | I16: =I9-I6 | ... AW16: =AW9-AW6 | AY16: 0.5 | AZ16: -6 | BB16: EUR NZD | BC16: =AL24 | BD16: 8 | BE16: {=_xlfn.XLOOKUP(MIN(ABS($AY$6:$AY$22 - MEDIAN(-2, 2, BC16))), ABS($AY$6:$AY$22 - MEDIAN(-2, 2, BC16)), $AZ$6:$AZ$22, "Error", 0)} | BF16: 0.005 | BG16: -6 | BH16: =BD16-BE16
A17: USD CAD | B17: =B9-B4 | C17: =C9-C4 | D17: =D9-D4 | E17: =E9-E4 | F17: =F9-F4 | G17: =G9-G4 | H17: =H9-H4 | I17: =I9-I4 | ... AW17: =AW9-AW4 | AY17: 0.75 | AZ17: -8 | BB17: GBP USD | BC17: =AL25 | BD17: -6 | BE17: {=_xlfn.XLOOKUP(MIN(ABS($AY$6:$AY$22 - MEDIAN(-2, 2, BC17))), ABS($AY$6:$AY$22 - MEDIAN(-2, 2, BC17)), $AZ$6:$AZ$22, "Error", 0)} | BF17: 0.0075 | BG17: -8 | BH17: =BD17-BE17
A18: EUR USD | B18: =B10-B9 | C18: =C10-C9 | D18: =D10-D9 | E18: =E10-E9 | F18: =F10-F9 | G18: =G10-G9 | H18: =H10-H9 | I18: =I10-I9 | ... AW18: =AW10-AW9 | AY18: 1 | AZ18: -10 | BB18: GBP JPY | BC18: =AL26 | BD18: 8 | BE18: {=_xlfn.XLOOKUP(MIN(ABS($AY$6:$AY$22 - MEDIAN(-2, 2, BC18))), ABS($AY$6:$AY$22 - MEDIAN(-2, 2, BC18)), $AZ$6:$AZ$22, "Error", 0)} | BF18: 0.01 | BG18: -10 | BH18: =BD18-BE18
A19: EUR JPY | B19: =B10-B5 | C19: =C10-C5 | D19: =D10-D5 | E19: =E10-E5 | F19: =F10-F5 | G19: =G10-G5 | H19: =H10-H5 | I19: =I10-I5 | ... AW19: =AW10-AW5 | AY19: 1.25 | AZ19: 6 | BB19: GBP CHF | BC19: =AL27 | BD19: 10 | BE19: {=_xlfn.XLOOKUP(MIN(ABS($AY$6:$AY$22 - MEDIAN(-2, 2, BC19))), ABS($AY$6:$AY$22 - MEDIAN(-2, 2, BC19)), $AZ$6:$AZ$22, "Error", 0)} | BF19: 0.0125 | BG19: 6 | BH19: =BD19-BE19
A20: EUR CHF | B20: =B10-B6 | C20: =C10-C6 | D20: =D10-D6 | E20: =E10-E6 | F20: =F10-F6 | G20: =G10-G6 | H20: =H10-H6 | I20: =I10-I6 | ... AW20: =AW10-AW6 | AY20: 1.5 | AZ20: 8 | BB20: GBP CAD | BC20: =AL28 | BD20: -8 | BE20: {=_xlfn.XLOOKUP(MIN(ABS($AY$6:$AY$22 - MEDIAN(-2, 2, BC20))), ABS($AY$6:$AY$22 - MEDIAN(-2, 2, BC20)), $AZ$6:$AZ$22, "Error", 0)} | BF20: 0.015 | BG20: 8 | BH20: =BD20-BE20
A21: EUR GBP | B21: =B10-B8 | C21: =C10-C8 | D21: =D10-D8 | E21: =E10-E8 | F21: =F10-F8 | G21: =G10-G8 | H21: =H10-H8 | I21: =I10-I8 | ... AW21: =AW10-AW8 | AY21: 1.75 | AZ21: 9 | BB21: GBP AUD | BC21: =AL29 | BD21: 8 | BE21: {=_xlfn.XLOOKUP(MIN(ABS($AY$6:$AY$22 - MEDIAN(-2, 2, BC21))), ABS($AY$6:$AY$22 - MEDIAN(-2, 2, BC21)), $AZ$6:$AZ$22, "Error", 0)} | BF21: 0.0175 | BG21: 9 | BH21: =BD21-BE21
A22: EUR CAD | B22: =B10-B4 | C22: =C10-C4 | D22: =D10-D4 | E22: =E10-E4 | F22: =F10-F4 | G22: =G10-G4 | H22: =H10-H4 | I22: =I10-I4 | ... AW22: =AW10-AW4 | AY22: 2 | AZ22: 10 | BB22: GBP NZD | BC22: =AL30 | BD22: -6 | BE22: {=_xlfn.XLOOKUP(MIN(ABS($AY$6:$AY$22 - MEDIAN(-2, 2, BC22))), ABS($AY$6:$AY$22 - MEDIAN(-2, 2, BC22)), $AZ$6:$AZ$22, "Error", 0)} | BF22: 0.02 | BG22: 10 | BH22: =BD22-BE22
A23: EUR AUD | B23: 0 | C23: 0 | D23: 0 | E23: 0 | F23: 0 | G23: 0 | H23: 0 | I23: 0 | J23: 0 | K23: 0 | L23: 0 | M23: 0 | N23: 0 | O23: 0 | P23: 0 | Q23: 0 | R23: 0 | S23: 0 | T23: 0 | U23: 0 | V23: 0 | W23: 0 | X23: 0 | Y23: 0 | Z23: 0 | AA23: 0 | AB23: 0 | AC23: =AC10-AC3 | AD23: =AD10-AD3 | AE23: =AE10-AE3 | AF23: =AF10-AF3 | AG23: =AG10-AG3 | AH23: =AH10-AH3 | AI23: =AI10-AI3 | AJ23: =AJ10-AJ3 | ... AW23: =AW10-AW3 | BB23: CHF JPY | BC23: =AL31 | BD23: 4 | BE23: {=_xlfn.XLOOKUP(MIN(ABS($AY$6:$AY$22 - MEDIAN(-2, 2, BC23))), ABS($AY$6:$AY$22 - MEDIAN(-2, 2, BC23)), $AZ$6:$AZ$22, "Error", 0)} | BH23: =BD23-BE23
A24: EUR NZD | B24: =B10-B7 | C24: =C10-C7 | D24: =D10-D7 | E24: =E10-E7 | F24: =F10-F7 | G24: =G10-G7 | H24: =H10-H7 | I24: =I10-I7 | ... AW24: =AW10-AW7 | BB24: AUD USD | BC24: =AL32 | BD24: 8 | BE24: {=_xlfn.XLOOKUP(MIN(ABS($AY$6:$AY$22 - MEDIAN(-2, 2, BC24))), ABS($AY$6:$AY$22 - MEDIAN(-2, 2, BC24)), $AZ$6:$AZ$22, "Error", 0)} | BH24: =BD24-BE24
A25: GBP USD | B25: =B8-B9 | C25: =C8-C9 | D25: =D8-D9 | E25: =E8-E9 | F25: =F8-F9 | G25: =G8-G9 | H25: =H8-H9 | I25: =I8-I9 | ... AW25: =AW8-AW9 | BB25: AUD CHF | BC25: =AL33 | BD25: 10 | BE25: {=_xlfn.XLOOKUP(MIN(ABS($AY$6:$AY$22 - MEDIAN(-2, 2, BC25))), ABS($AY$6:$AY$22 - MEDIAN(-2, 2, BC25)), $AZ$6:$AZ$22, "Error", 0)} | BH25: =BD25-BE25
A26: GBP JPY | B26: =B8-B5 | C26: =C8-C5 | D26: =D8-D5 | E26: =E8-E5 | F26: =F8-F5 | G26: =G8-G5 | H26: =H8-H5 | I26: =I8-I5 | ... AW26: =AW8-AW5 | BB26: AUD JPY | BC26: =AL34 | BD26: 10 | BE26: {=_xlfn.XLOOKUP(MIN(ABS($AY$6:$AY$22 - MEDIAN(-2, 2, BC26))), ABS($AY$6:$AY$22 - MEDIAN(-2, 2, BC26)), $AZ$6:$AZ$22, "Error", 0)} | BH26: =BD26-BE26
A27: GBP CHF | B27: =B8-B6 | C27: =C8-C6 | D27: =D8-D6 | E27: =E8-E6 | F27: =F8-F6 | G27: =G8-G6 | H27: =H8-H6 | I27: =I8-I6 | ... AW27: =AW8-AW6 | BB27: AUD NZD | BC27: =AL35 | BD27: 6 | BE27: {=_xlfn.XLOOKUP(MIN(ABS($AY$6:$AY$22 - MEDIAN(-2, 2, BC27))), ABS($AY$6:$AY$22 - MEDIAN(-2, 2, BC27)), $AZ$6:$AZ$22, "Error", 0)} | BH27: =BD27-BE27
A28: GBP CAD | B28: =B8-B4 | C28: =C8-C4 | D28: =D8-D4 | E28: =E8-E4 | F28: =F8-F4 | G28: =G8-G4 | H28: =H8-H4 | I28: =I8-I4 | ... AW28: =AW8-AW4 | BB28: AUD CAD | BC28: =AL36 | BD28: 8 | BE28: {=_xlfn.XLOOKUP(MIN(ABS($AY$6:$AY$22 - MEDIAN(-2, 2, BC28))), ABS($AY$6:$AY$22 - MEDIAN(-2, 2, BC28)), $AZ$6:$AZ$22, "Error", 0)} | BH28: =BD28-BE28
A29: GBP AUD | B29: =B8-B3 | C29: =C8-C3 | D29: =D8-D3 | E29: =E8-E3 | F29: =F8-F3 | G29: =G8-G3 | H29: =H8-H3 | I29: =I8-I3 | ... AW29: =AW8-AW3 | BB29: CAD JPY | BC29: =AL37 | BD29: -8 | BE29: {=_xlfn.XLOOKUP(MIN(ABS($AY$6:$AY$22 - MEDIAN(-2, 2, BC29))), ABS($AY$6:$AY$22 - MEDIAN(-2, 2, BC29)), $AZ$6:$AZ$22, "Error", 0)} | BH29: =BD29-BE29
A30: GBP NZD | B30: =B8-B7 | C30: =C8-C7 | D30: =D8-D7 | E30: =E8-E7 | F30: =F8-F7 | G30: =G8-G7 | H30: =H8-H7 | I30: =I8-I7 | ... AW30: =AW8-AW7 | BC30: 0.7 | BD30: -8 | BE30: {=_xlfn.XLOOKUP(MIN(ABS($AY$6:$AY$22 - MEDIAN(-2, 2, BC30))), ABS($AY$6:$AY$22 - MEDIAN(-2, 2, BC30)), $AZ$6:$AZ$22, "Error", 0)} | BH30: =BD30-BE30
A31: CHF JPY | B31: =B6-B5 | C31: =C6-C5 | D31: =D6-D5 | E31: =E6-E5 | F31: =F6-F5 | G31: =G6-G5 | H31: =H6-H5 | I31: =I6-I5 | ... AW31: =AW6-AW5 | BC31: 0.6 | BD31: -6 | BE31: {=_xlfn.XLOOKUP(MIN(ABS($AY$6:$AY$22 - MEDIAN(-2, 2, BC31))), ABS($AY$6:$AY$22 - MEDIAN(-2, 2, BC31)), $AZ$6:$AZ$22, "Error", 0)} | BH31: =BD31-BE31
A32: AUD USD | B32: =B3-B9 | C32: =C3-C9 | D32: =D3-D9 | E32: =E3-E9 | F32: =F3-F9 | G32: =G3-G9 | H32: =H3-H9 | I32: =I3-I9 | ... AW32: =AW3-AW9
A33: AUD CHF | B33: =B3-B6 | C33: =C3-C6 | D33: =D3-D6 | E33: =E3-E6 | F33: =F3-F6 | G33: =G3-G6 | H33: =H3-H6 | I33: =I3-I6 | ... AW33: =AW3-AW6
A34: AUD JPY | B34: =B3-B5 | C34: =C3-C5 | D34: =D3-D5 | E34: =E3-E5 | F34: =F3-F5 | G34: =G3-G5 | H34: =H3-H5 | I34: =I3-I5 | ... AW34: =AW3-AW5
A35: AUD NZD | B35: =B3-B7 | C35: =C3-C7 | D35: =D3-D7 | E35: =E3-E7 | F35: =F3-F7 | G35: =G3-G7 | H35: =H3-H7 | I35: =I3-I7 | ... AW35: =AW3-AW7
A36: AUD CAD | B36: =B3-B4 | C36: =C3-C4 | D36: =D3-D4 | E36: =E3-E4 | F36: =F3-F4 | G36: =G3-G4 | H36: =H3-H4 | I36: =I3-I4 | ... AW36: =AW3-AW4
A37: CAD JPY | B37: =B4-B5 | C37: =C4-C5 | D37: =D4-D5 | E37: =E4-E5 | F37: =F4-F5 | G37: =G4-G5 | H37: =H4-H5 | I37: =I4-I5 | ... AW37: =AW4-AW5
A43: Paire | B43: 44927 | C43: 44958 | D43: 44986 | E43: 45017 | F43: 45047 | G43: 45078 | H43: 45108 | I43: 45139 | J43: 45170 | K43: 45200 | L43: 45231 | M43: 45261 | N43: 45292 | O43: 45323 | P43: 45352 | Q43: 45383 | R43: 45413 | S43: 45444 | T43: 45474 | U43: 45505 | V43: 45536 | W43: 45566 | X43: 45597 | Y43: 45627 | Z43: 45658 | AA43: 45689 | AB43: 45717 | AC43: 45748 | AD43: 45778 | AE43: 45809 | AF43: 45839 | AG43: 45870 | AH43: 45901 | AI43: 45931 | AJ43: 45962 | AK43: 45992 | AL43: 46023 | AM43: 46054 | AN43: 46082 | AO43: 46113 | AP43: 46143 | AQ43: 46174 | AR43: 46204 | AS43: 46235 | AT43: 46266 | AU43: 46296 | AV43: 46327 | AW43: 46357
A44: USD JPY | B44: {=_xlfn.XLOOKUP(MIN(ABS($AY$6:$AY$22 - MEDIAN(-2, 2, B15))), ABS($AY$6:$AY$22 - MEDIAN(-2, 2, B15)), $AZ$6:$AZ$22, "Error", 0)} | C44: {=_xlfn.XLOOKUP(MIN(ABS($AY$6:$AY$22 - MEDIAN(-2, 2, C15))), ABS($AY$6:$AY$22 - MEDIAN(-2, 2, C15)), $AZ$6:$AZ$22, "Error", 0)} | D44: {=_xlfn.XLOOKUP(MIN(ABS($AY$6:$AY$22 - MEDIAN(-2, 2, D15))), ABS($AY$6:$AY$22 - MEDIAN(-2, 2, D15)), $AZ$6:$AZ$22, "Error", 0)} | E44: {=_xlfn.XLOOKUP(MIN(ABS($AY$6:$AY$22 - MEDIAN(-2, 2, E15))), ABS($AY$6:$AY$22 - MEDIAN(-2, 2, E15)), $AZ$6:$AZ$22, "Error", 0)} | F44: {=_xlfn.XLOOKUP(MIN(ABS($AY$6:$AY$22 - MEDIAN(-2, 2, F15))), ABS($AY$6:$AY$22 - MEDIAN(-2, 2, F15)), $AZ$6:$AZ$22, "Error", 0)} | G44: {=_xlfn.XLOOKUP(MIN(ABS($AY$6:$AY$22 - MEDIAN(-2, 2, G15))), ABS($AY$6:$AY$22 - MEDIAN(-2, 2, G15)), $AZ$6:$AZ$22, "Error", 0)} | H44: {=_xlfn.XLOOKUP(MIN(ABS($AY$6:$AY$22 - MEDIAN(-2, 2, H15))), ABS($AY$6:$AY$22 - MEDIAN(-2, 2, H15)), $AZ$6:$AZ$22, "Error", 0)} | I44: {=_xlfn.XLOOKUP(MIN(ABS($AY$6:$AY$22 - MEDIAN(-2, 2, I15))), ABS($AY$6:$AY$22 - MEDIAN(-2, 2, I15)), $AZ$6:$AZ$22, "Error", 0)} | ... AW44: {=_xlfn.XLOOKUP(MIN(ABS($AY$6:$AY$22 - MEDIAN(-2, 2, AW15))), ABS($AY$6:$AY$22 - MEDIAN(-2, 2, AW15)), $AZ$6:$AZ$22, "Error", 0)}
A45: USD CHF | B45: {=_xlfn.XLOOKUP(MIN(ABS($AY$6:$AY$22 - MEDIAN(-2, 2, B16))), ABS($AY$6:$AY$22 - MEDIAN(-2, 2, B16)), $AZ$6:$AZ$22, "Error", 0)} | C45: {=_xlfn.XLOOKUP(MIN(ABS($AY$6:$AY$22 - MEDIAN(-2, 2, C16))), ABS($AY$6:$AY$22 - MEDIAN(-2, 2, C16)), $AZ$6:$AZ$22, "Error", 0)} | D45: {=_xlfn.XLOOKUP(MIN(ABS($AY$6:$AY$22 - MEDIAN(-2, 2, D16))), ABS($AY$6:$AY$22 - MEDIAN(-2, 2, D16)), $AZ$6:$AZ$22, "Error", 0)} | E45: {=_xlfn.XLOOKUP(MIN(ABS($AY$6:$AY$22 - MEDIAN(-2, 2, E16))), ABS($AY$6:$AY$22 - MEDIAN(-2, 2, E16)), $AZ$6:$AZ$22, "Error", 0)} | F45: {=_xlfn.XLOOKUP(MIN(ABS($AY$6:$AY$22 - MEDIAN(-2, 2, F16))), ABS($AY$6:$AY$22 - MEDIAN(-2, 2, F16)), $AZ$6:$AZ$22, "Error", 0)} | G45: {=_xlfn.XLOOKUP(MIN(ABS($AY$6:$AY$22 - MEDIAN(-2, 2, G16))), ABS($AY$6:$AY$22 - MEDIAN(-2, 2, G16)), $AZ$6:$AZ$22, "Error", 0)} | H45: {=_xlfn.XLOOKUP(MIN(ABS($AY$6:$AY$22 - MEDIAN(-2, 2, H16))), ABS($AY$6:$AY$22 - MEDIAN(-2, 2, H16)), $AZ$6:$AZ$22, "Error", 0)} | I45: {=_xlfn.XLOOKUP(MIN(ABS($AY$6:$AY$22 - MEDIAN(-2, 2, I16))), ABS($AY$6:$AY$22 - MEDIAN(-2, 2, I16)), $AZ$6:$AZ$22, "Error", 0)} | ... AW45: {=_xlfn.XLOOKUP(MIN(ABS($AY$6:$AY$22 - MEDIAN(-2, 2, AW16))), ABS($AY$6:$AY$22 - MEDIAN(-2, 2, AW16)), $AZ$6:$AZ$22, "Error", 0)}
A46: USD CAD | B46: {=_xlfn.XLOOKUP(MIN(ABS($AY$6:$AY$22 - MEDIAN(-2, 2, B17))), ABS($AY$6:$AY$22 - MEDIAN(-2, 2, B17)), $AZ$6:$AZ$22, "Error", 0)} | C46: {=_xlfn.XLOOKUP(MIN(ABS($AY$6:$AY$22 - MEDIAN(-2, 2, C17))), ABS($AY$6:$AY$22 - MEDIAN(-2, 2, C17)), $AZ$6:$AZ$22, "Error", 0)} | D46: {=_xlfn.XLOOKUP(MIN(ABS($AY$6:$AY$22 - MEDIAN(-2, 2, D17))), ABS($AY$6:$AY$22 - MEDIAN(-2, 2, D17)), $AZ$6:$AZ$22, "Error", 0)} | E46: {=_xlfn.XLOOKUP(MIN(ABS($AY$6:$AY$22 - MEDIAN(-2, 2, E17))), ABS($AY$6:$AY$22 - MEDIAN(-2, 2, E17)), $AZ$6:$AZ$22, "Error", 0)} | F46: {=_xlfn.XLOOKUP(MIN(ABS($AY$6:$AY$22 - MEDIAN(-2, 2, F17))), ABS($AY$6:$AY$22 - MEDIAN(-2, 2, F17)), $AZ$6:$AZ$22, "Error", 0)} | G46: {=_xlfn.XLOOKUP(MIN(ABS($AY$6:$AY$22 - MEDIAN(-2, 2, G17))), ABS($AY$6:$AY$22 - MEDIAN(-2, 2, G17)), $AZ$6:$AZ$22, "Error", 0)} | H46: {=_xlfn.XLOOKUP(MIN(ABS($AY$6:$AY$22 - MEDIAN(-2, 2, H17))), ABS($AY$6:$AY$22 - MEDIAN(-2, 2, H17)), $AZ$6:$AZ$22, "Error", 0)} | I46: {=_xlfn.XLOOKUP(MIN(ABS($AY$6:$AY$22 - MEDIAN(-2, 2, I17))), ABS($AY$6:$AY$22 - MEDIAN(-2, 2, I17)), $AZ$6:$AZ$22, "Error", 0)} | ... AW46: {=_xlfn.XLOOKUP(MIN(ABS($AY$6:$AY$22 - MEDIAN(-2, 2, AW17))), ABS($AY$6:$AY$22 - MEDIAN(-2, 2, AW17)), $AZ$6:$AZ$22, "Error", 0)}
...

Sheet FX RESERVE DATA
A2: BOP | B2: 44562 | C2: 44593 | D2: 44621 | E2: 44652 | F2: 44682 | G2: 44713 | H2: 44743 | I2: 44774 | J2: 44805 | K2: 44835 | L2: 44866 | M2: 44896 | N2: 44927 | O2: 44958 | P2: 44986 | Q2: 45017 | R2: 45047 | S2: 45078 | T2: 45108 | U2: 45139 | V2: 45170 | W2: 45200 | X2: 45231 | Y2: 45261 | Z2: 45292 | AA2: 45323 | AB2: 45352 | AC2: 45383 | AD2: 45413 | AE2: 45444 | AF2: 45474 | AG2: 45505 | AH2: 45536 | AI2: 45566 | AJ2: 45597 | AK2: 45627 | AL2: 45658 | AM2: 45689 | AN2: 45717 | AO2: 45748 | AP2: 45778 | AQ2: 45809 | AR2: 45839 | AS2: 45870 | AT2: 45901 | AU2: 45931 | AV2: 45962 | AW2: 45992 | AX2: 46023 | AY2: 46054 | AZ2: 46082 | BA2: 46113 | BB2: 46143 | BC2: 46174 | BD2: 46204 | BE2: 46235 | BF2: 46266 | BG2: 46296 | BH2: 46327 | BI2: 46357
A3: Australia | B3: 35902 | C3: 36120 | D3: 36276 | E3: 34607 | F3: 35095 | G3: 34447 | H3: 35634 | I3: 35922 | J3: 35037 | K3: 36113 | L3: 39040 | M3: 38480 | N3: 38149 | O3: 35320 | P3: 36375 | Q3: 38679 | R3: 36115 | S3: 36911 | T3: 38215 | U3: 38434 | V3: 35744 | W3: 35888 | X3: 38009 | Y3: 40897 | Z3: 35026 | AA3: 35126 | AB3: 34212 | AC3: 33803 | AD3: 35618 | AE3: 37644 | AF3: 36729 | AG3: 40610 | AH3: 39957 | AI3: 39030 | AJ3: 39287 | AK3: 39576 | AL3: 40770 | AM3: 41970 | AN3: 41098 | AO3: 39891 | AP3: 41757 | AQ3: 39970 | AR3: 39476 | AS3: 40717 | AT3: 42175 | AU3: 41482 | AV3: 42782 | AW3: 44962 | AX3: 40964 | AY3: 42106 | AZ3: 41982 | BA3: 41544 | BB3: 40705 | BC3: 41187 | BD3: 46150 | BE3: 46150 | BF3: 46150 | BK3: -2000 | BL3: 10
A4: Canada | B4: 76095 | C4: 74519 | D4: 75387 | E4: 78056 | F4: 80218 | G4: 79017 | H4: 79458 | I4: 80964 | J4: 76411 | K4: 77353 | L4: 79282 | M4: 79729 | N4: 82059 | O4: 80984 | P4: 81835 | Q4: 86299 | R4: 86006 | S4: 86474 | T4: 86488 | U4: 86550 | V4: 84626 | W4: 85070 | X4: 87525 | Y4: 89914 | Z4: 88305 | AA4: 88288 | AB4: 89875 | AC4: 93627 | AD4: 95171 | AE4: 94963 | AF4: 95929 | AG4: 97153 | AH4: 99088 | AI4: 94663 | AJ4: 94505 | AK4: 93879 | AL4: 90209 | AM4: 91801 | AN4: 97780 | AO4: 95814 | AP4: 96089 | AQ4: 98529 | AR4: 97607 | AS4: 98412 | AT4: 97141 | AU4: 99676 | AV4: 98608 | AW4: 98396 | AX4: 98880 | AY4: 98087 | AZ4: 97132 | BA4: 96496 | BB4: 96721 | BC4: 96543 | BD4: 96979 | BE4: 97000 | BF4: 97000 | BK4: -1800 | BL4: 9
A5: Japan | B5: 1264244 | C5: 1259159 | D5: 1230520 | E5: 1199561 | F5: 1208699 | G5: 1192911 | H5: 1206630 | I5: 1176896 | J5: 1125304 | K5: 1082452 | L5: 1109364 | M5: 1108189 | N5: 1126868 | O5: 1106343 | P5: 1134005 | Q5: 1142230 | R5: 1132162 | S5: 1126104 | T5: 1130301 | U5: 1132621 | V5: 1120048 | W5: 1117193 | X5: 1146719 | Y5: 1170437 | Z5: 1169506 | AA5: 1158491 | AB5: 1163521 | AC5: 1149316 | AD5: 1100113 | AE5: 1100691 | AF5: 1084573 | AG5: 1097528 | AH5: 1112931 | AI5: 1095601 | AJ5: 1099052 | AK5: 1092306 | AL5: 1096788 | AM5: 1108410 | AN5: 1118981 | AO5: 1136746 | AP5: 1137098 | AQ5: 1151692 | AR5: 1143537 | AS5: 1158765 | AT5: 1165059 | AU5: 1166724 | AV5: 1173675 | AW5: 1180501 | AX5: 1186456 | AY5: 1196112 | AZ5: 1177804 | BA5: 1185242 | BB5: 1109822 | BC5: 1106270 | BD5: 1105474 | BE5: 1105474 | BF5: 1105474 | BK5: -1600 | BL5: 8
A6: Switzerland | B6: 1017415.3 | C6: 1021205.1 | D6: 985078.61 | E6: 953465.07 | F6: 964651.06 | G6: 887448.48 | H6: 887071.83 | I6: 877562.25 | J6: 822339.5 | K6: 814555.69 | L6: 832856.42 | M6: 848509.64 | N6: 850924.63 | O6: 822856.41 | P6: 813080.99 | Q6: 819722.55 | R6: 805716.7 | S6: 808190.39 | T6: 803228.9 | U6: 785734.47 | V6: 741365.63 | W6: 724518.23 | X6: 733629.27 | Y6: 779970.87 | Z6: 773682.26 | AA6: 771212.31 | AB6: 793167.83 | AC6: 787294.66 | AD6: 795406.01 | AE6: 791623.08 | AF6: 801978.47 | AG6: 816745.33 | AH6: 847502.5 | AI6: 831453.68 | AJ6: 822005.26 | AK6: 808024.55 | AL6: 809259.31 | AM6: 814973.06 | AN6: 822339.5 | AO6: 854313.96 | AP6: 854058.97 | AQ6: 894234.6 | AR6: 880000.59 | AS6: 892783.55 | AT6: 911657.16 | AU6: 902110.07 | AV6: 903578.55 | AW6: 914657.72 | AX6: 926074.95 | AY6: 923641.88 | AZ6: 901037.53 | BA6: 912992.02 | BB6: 909891 | BC6: 938060 | BD6: 921227 | BE6: 921227 | BF6: 921227 | BK6: -1400 | BL6: 7
A7: New Zealand | B7: 11132 | C7: 11012 | D7: 12794 | E7: 8547 | F7: 11076 | G7: 9127 | H7: 10034 | I7: 8685 | J7: 8231 | K7: 6716 | L7: 11377 | M7: 11061 | N7: 11419 | O7: 13462 | P7: 11364 | Q7: 12534 | R7: 12544 | S7: 9934 | T7: 13615 | U7: 12940 | V7: 13708 | W7: 12577 | X7: 15987 | Y7: 12113 | Z7: 14893 | AA7: 15975 | AB7: 12891 | AC7: 15712 | AD7: 14660 | AE7: 14485 | AF7: 17689 | AG7: 17055 | AH7: 17316 | AI7: 20275 | AJ7: 19174 | AK7: 18836 | AL7: 23379 | AM7: 24951 | AN7: 22603 | AO7: 23387 | AP7: 24600 | AQ7: 24320 | AR7: 25170 | AS7: 24884 | AT7: 24006 | AU7: 24202 | AV7: 28622 | AW7: 24781 | AX7: 27581 | AY7: 25799 | AZ7: 31400 | BA7: 27963 | BB7: 29365 | BC7: 26165 | BD7: 30563 | BE7: 30563 | BF7: 30563 | BK7: -1200 | BL7: 6
A8: United Kingdom | B8: 120411.92 | C8: 120532.75 | D8: 123104.96 | E8: 115053.03 | F8: 112608.82 | G8: 110336.99 | H8: 108203.65 | I8: 107780.62 | J8: 97646.819 | K8: 101927.45 | L8: 108268.35 | M8: 110285.51 | N8: 108424.78 | O8: 102781.8 | P8: 105046.47 | Q8: 107719.01 | R8: 104068.46 | S8: 106042.77 | T8: 110108.85 | U8: 109175.59 | V8: 103971.13 | W8: 103736.91 | X8: 106107.64 | Y8: 108765.24 | Z8: 105698.52 | AA8: 104694.58 | AB8: 105493.85 | AC8: 100104.93 | AD8: 103539.63 | AE8: 102150.43 | AF8: 106238.07 | AG8: 107970.45 | AH8: 106798.85 | AI8: 104268.48 | AJ8: 104730.56 | AK8: 102683.2 | AL8: 102719.52 | AM8: 104175.92 | AN8: 106345.15 | AO8: 111229.13 | AP8: 112666.82 | AQ8: 116903.29 | AR8: 115962.86 | AS8: 118608.23 | AT8: 122086.56 | AU8: 121043.62 | AV8: 123015.11 | AW8: 123790.23 | AX8: 123927.95 | AY8: 126625.3 | AZ8: 126449.82 | BA8: 122681.06 | BB8: 125316 | BC8: 125035 | BD8: 124927 | BE8: 124927 | BF8: 124927 | BK8: -1000 | BL8: 5
A9: United States | B9: 40353.171 | C9: 40387.912 | D9: 39252.167 | E9: 37053.645 | F9: 37610.21 | G9: 36273.389 | H9: 35946.732 | I9: 35098.677 | J9: 33935.231 | K9: 33821.296 | L9: 35619.669 | M9: 37208.746 | N9: 37755.474 | O9: 36604.928 | P9: 37565.901 | Q9: 37627.61 | R9: 36459.008 | S9: 36643.742 | T9: 37113.847 | U9: 36448.63 | V9: 35613.44 | W9: 35213.519 | X9: 36302.629 | Y9: 37316.475 | Z9: 36438.875 | AA9: 36076.821 | AB9: 35990.22 | AC9: 35315.933 | AD9: 35757.623 | AE9: 35242.83 | AF9: 36357.415 | AG9: 37318.045 | AH9: 37804.752 | AI9: 36337.084 | AJ9: 35805.154 | AK9: 34865.011 | AL9: 35207.948 | AM9: 35597.682 | AN9: 36586.626 | AO9: 38564.764 | AP9: 38470.276 | AQ9: 39471.181 | AR9: 38203.046 | AS9: 39161.137 | AT9: 39204.554 | AU9: 38314.056 | AV9: 38330 | AW9: 38641 | AX9: 39222.229 | AY9: 38992.34 | AZ9: 38121 | BA9: 38121 | BB9: 39000 | BC9: 38591 | BD9: 38992 | BE9: 38992 | BF9: 38992 | BK9: -800 | BL9: 4
A10: EURO AREA | B10: 312546 | C10: 313471 | D10: 309506 | E10: 305206 | F10: 307840 | G10: 305918 | H10: 308938 | I10: 306005 | J10: 303179 | K10: 304221 | L10: 309061 | M10: 315345 | N10: 310949 | O10: 293900 | P10: 297950 | Q10: 295116 | R10: 292792 | S10: 293016 | T10: 294678 | U10: 292405 | V10: 285245 | W10: 287457 | X10: 295267 | Y10: 301470 | Z10: 299104 | AA10: 298787 | AB10: 298344 | AC10: 295492 | AD10: 298861 | AE10: 301235 | AF10: 301245 | AG10: 300873 | AH10: 303818 | AI10: 299382 | AJ10: 300478 | AK10: 300657 | AL10: 298104 | AM10: 302136 | AN10: 304980 | AO10: 310594 | AP10: 312792 | AQ10: 316343 | AR10: 314415 | AS10: 316890 | AT10: 322760 | AU10: 322351 | AV10: 325548 | AW10: 334436 | AX10: 343000 | AY10: 343000 | AZ10: 348000 | BA10: 359000 | BB10: 352000 | BC10: 340574 | BD10: 342550 | BE10: 342550 | BF10: 342550 | BK10: -600 | BL10: 3
BK11: -400 | BL11: 2
A12: Monthly Change | BK12: -200 | BL12: 1
A13: BOP | B13: 44562 | C13: 44593 | D13: 44621 | E13: 44652 | F13: 44682 | G13: 44713 | H13: 44743 | I13: 44774 | J13: 44805 | K13: 44835 | L13: 44866 | M13: 44896 | N13: 44927 | O13: 44958 | P13: 44986 | Q13: 45017 | R13: 45047 | S13: 45078 | T13: 45108 | U13: 45139 | V13: 45170 | W13: 45200 | X13: 45231 | Y13: 45261 | Z13: 45292 | AA13: 45323 | AB13: 45352 | AC13: 45383 | AD13: 45413 | AE13: 45444 | AF13: 45474 | AG13: 45505 | AH13: 45536 | AI13: 45566 | AJ13: 45597 | AK13: 45627 | AL13: 45658 | AM13: 45689 | AN13: 45717 | AO13: 45748 | AP13: 45778 | AQ13: 45809 | AR13: 45839 | AS13: 45870 | AT13: 45901 | AU13: 45931 | AV13: 45962 | AW13: 45992 | AX13: 46023 | AY13: 46054 | AZ13: 46082 | BA13: 46113 | BB13: 46143 | BC13: 46174 | BD13: 46204 | BE13: 46235 | BF13: 46266 | BG13: 46296 | BH13: 46327 | BI13: 46357 | BK13: 0 | BL13: 0
A14: Australia | C14: =C3-B3 | D14: =D3-C3 | E14: =E3-D3 | F14: =F3-E3 | G14: =G3-F3 | H14: =H3-G3 | I14: =I3-H3 | J14: =J3-I3 | ... BI14: =BI3-BH3 | BJ14: =MAX(C14:BA14) | BK14: 200 | BL14: -1 | BM14: =MIN(C14:BA14)
A15: Canada | C15: =C4-B4 | D15: =D4-C4 | E15: =E4-D4 | F15: =F4-E4 | G15: =G4-F4 | H15: =H4-G4 | I15: =I4-H4 | J15: =J4-I4 | ... BI15: =BI4-BH4 | BJ15: =MAX(C15:BA15) | BK15: 400 | BL15: -2 | BM15: =MIN(C15:BA15)
A16: Japan | C16: =C5-B5 | D16: =D5-C5 | E16: =E5-D5 | F16: =F5-E5 | G16: =G5-F5 | H16: =H5-G5 | I16: =I5-H5 | J16: =J5-I5 | ... BI16: =BI5-BH5 | BJ16: =MAX(C16:BA16) | BK16: 600 | BL16: -3 | BM16: =MIN(C16:BA16)
A17: Switzerland | C17: =C6-B6 | D17: =D6-C6 | E17: =E6-D6 | F17: =F6-E6 | G17: =G6-F6 | H17: =H6-G6 | I17: =I6-H6 | J17: =J6-I6 | ... AW17: =AW6-AV6 | AX17: 11079.17 | AY17: 11080.17 | AZ17: 11081.17 | BA17: 11082.17 | BB17: 11083.17 | BC17: 11084.17 | BD17: 11085.17 | BE17: 11086.17 | BF17: 11087.17 | BG17: 11088.17 | BH17: 11089.17 | BI17: 11090.17 | BJ17: =MAX(C17:BA17) | BK17: 800 | BL17: -4 | BM17: =MIN(C17:BA17)
A18: New Zealand | C18: =C7-B7 | D18: =D7-C7 | E18: =E7-D7 | F18: =F7-E7 | G18: =G7-F7 | H18: =H7-G7 | I18: =I7-H7 | J18: =J7-I7 | ... BI18: =BI7-BH7 | BJ18: =MAX(C18:BA18) | BK18: 1000 | BL18: -5 | BM18: =MIN(C18:BA18)
A19: United Kingdom | C19: =C8-B8 | D19: =D8-C8 | E19: =E8-D8 | F19: =F8-E8 | G19: =G8-F8 | H19: =H8-G8 | I19: =I8-H8 | J19: =J8-I8 | ... BI19: =BI8-BH8 | BJ19: =MAX(C19:BA19) | BK19: 1200 | BL19: -6 | BM19: =MIN(C19:BA19)
A20: United States | C20: =C9-B9 | D20: =D9-C9 | E20: =E9-D9 | F20: =F9-E9 | G20: =G9-F9 | H20: =H9-G9 | I20: =I9-H9 | J20: =J9-I9 | ... BI20: =BI9-BH9 | BJ20: =MAX(C20:BA20) | BK20: 1400 | BL20: -7 | BM20: =MIN(C20:BA20)
A21: EURO AREA | C21: =C10-B10 | D21: =D10-C10 | E21: =E10-D10 | F21: =F10-E10 | G21: =G10-F10 | H21: =H10-G10 | I21: =I10-H10 | J21: =J10-I10 | ... BI21: =BI10-BH10 | BJ21: =MAX(C21:BA21) | BK21: 1600 | BL21: -8 | BM21: =MIN(C21:BA21)
BK22: 1800 | BL22: -9
A23: 12 Month Average | BK23: 2000 | BL23: -10
